Workbook

Sheet RÉCAPITULATIF
A1: FLUX BAGAGES — RÉCAPITULATIF — EI — AER LINGUS
A3: COMPTE RENDU DE SUPERVISION • SEPTEMBRE 2026 • EI — AER LINGUS
A5: DOSSIERS | D5: BAGAGES ATTENDUS | G5: SAUVÉS | J5: CHARGÉS | M5: NON CHARGÉS | P5: ANNULÉS | S5: TAGS EN DOUBLE
A6: =SUM(B14:B27) -> 302 | D6: =SUM(D14:D27) -> 17510 | G6: =SUM(E14:E27) -> 44 | J6: =SUM(F14:F27) -> 82 | M6: =SUM(G14:G27) -> 176 | P6: =SUM(H14:H27) -> 0 | S6: =MAX(BASE!$Q$6:$Q$1740) -> 0
A8: TAUX DE TRAITEMENT | D8: DOSSIERS TRAITÉS | G8: % SAUVÉS | J8: % CHARGÉS | M8: % NON CHARGÉS | P8: % ANNULÉS | S8: LIGNES CONCERNÉES
A9: =IFERROR((G6+J6+M6+P6)/A6,0) -> 1 | D9: =SUM(G6,J6,M6,P6) -> 302 | G9: =G6/$A$6 -> 0.14569536 | J9: =J6/$A$6 -> 0.27152318 | M9: =M6/$A$6 -> 0.58278146 | P9: =P6/$A$6 -> 0 | S9: =COUNTIF(BASE!$P$6:$P$1740,">1") -> 0
A12: RÉPARTITION PAR COMPAGNIE | AA12: COMPAGNIE | AB12: SAUVÉS | AC12: CHARGÉS | AD12: NON CHARGÉS | AE12: ANNULÉS
A13: CIE | B13: DOSSIERS | C13: BAG. TRAITÉS | D13: ATTENDUS | E13: SAUVÉS | F13: CHARGÉS | G13: NON CHARGÉS | H13: ANNULÉS | I13: TAUX SAUVÉS | AA13: EI | AB13: 44 | AC13: 82 | AD13: 176 | AE13: 0
A14: EI | B14: =COUNTIF(BASE!$B$6:$B$1740,A14) -> 302 | C14: =SUMIF(BASE!$B$6:$B$1740,A14,BASE!$F$6:$F$1740) -> 302 | D14: 17510 | E14: =COUNTIFS(BASE!$B$6:$B$1740,A14,BASE!$M$6:$M$1740,"SAUVÉ") -> 44 | F14: =COUNTIFS(BASE!$B$6:$B$1740,A14,BASE!$M$6:$M$1740,"CHARGÉ") -> 82 | G14: =COUNTIFS(BASE!$B$6:$B$1740,A14,BASE!$M$6:$M$1740,"NON CHARGÉ") -> 176 | H14: =COUNTIFS(BASE!$B$6:$B$1740,A14,BASE!$M$6:$M$1740,"ANNULÉ") -> 0 | I14: =IFERROR(E14/B14,0) -> 0.14569536
B15: =COUNTIF(BASE!$B$6:$B$1740,A15) -> 0 | C15: =SUMIF(BASE!$B$6:$B$1740,A15,BASE!$F$6:$F$1740) -> 0 | D15: 0 | E15: =COUNTIFS(BASE!$B$6:$B$1740,A15,BASE!$M$6:$M$1740,"SAUVÉ") -> 0 | F15: =COUNTIFS(BASE!$B$6:$B$1740,A15,BASE!$M$6:$M$1740,"CHARGÉ") -> 0 | G15: =COUNTIFS(BASE!$B$6:$B$1740,A15,BASE!$M$6:$M$1740,"NON CHARGÉ") -> 0 | H15: =COUNTIFS(BASE!$B$6:$B$1740,A15,BASE!$M$6:$M$1740,"ANNULÉ") -> 0 | I15: =IFERROR(E15/B15,0) -> 0
B16: =COUNTIF(BASE!$B$6:$B$1740,A16) -> 0 | C16: =SUMIF(BASE!$B$6:$B$1740,A16,BASE!$F$6:$F$1740) -> 0 | D16: 0 | E16: =COUNTIFS(BASE!$B$6:$B$1740,A16,BASE!$M$6:$M$1740,"SAUVÉ") -> 0 | F16: =COUNTIFS(BASE!$B$6:$B$1740,A16,BASE!$M$6:$M$1740,"CHARGÉ") -> 0 | G16: =COUNTIFS(BASE!$B$6:$B$1740,A16,BASE!$M$6:$M$1740,"NON CHARGÉ") -> 0 | H16: =COUNTIFS(BASE!$B$6:$B$1740,A16,BASE!$M$6:$M$1740,"ANNULÉ") -> 0 | I16: =IFERROR(E16/B16,0) -> 0
B17: =COUNTIF(BASE!$B$6:$B$1740,A17) -> 0 | C17: =SUMIF(BASE!$B$6:$B$1740,A17,BASE!$F$6:$F$1740) -> 0 | D17: 0 | E17: =COUNTIFS(BASE!$B$6:$B$1740,A17,BASE!$M$6:$M$1740,"SAUVÉ") -> 0 | F17: =COUNTIFS(BASE!$B$6:$B$1740,A17,BASE!$M$6:$M$1740,"CHARGÉ") -> 0 | G17: =COUNTIFS(BASE!$B$6:$B$1740,A17,BASE!$M$6:$M$1740,"NON CHARGÉ") -> 0 | H17: =COUNTIFS(BASE!$B$6:$B$1740,A17,BASE!$M$6:$M$1740,"ANNULÉ") -> 0 | I17: =IFERROR(E17/B17,0) -> 0
B18: =COUNTIF(BASE!$B$6:$B$1740,A18) -> 0 | C18: =SUMIF(BASE!$B$6:$B$1740,A18,BASE!$F$6:$F$1740) -> 0 | D18: 0 | E18: =COUNTIFS(BASE!$B$6:$B$1740,A18,BASE!$M$6:$M$1740,"SAUVÉ") -> 0 | F18: =COUNTIFS(BASE!$B$6:$B$1740,A18,BASE!$M$6:$M$1740,"CHARGÉ") -> 0 | G18: =COUNTIFS(BASE!$B$6:$B$1740,A18,BASE!$M$6:$M$1740,"NON CHARGÉ") -> 0 | H18: =COUNTIFS(BASE!$B$6:$B$1740,A18,BASE!$M$6:$M$1740,"ANNULÉ") -> 0 | I18: =IFERROR(E18/B18,0) -> 0
B19: =COUNTIF(BASE!$B$6:$B$1740,A19) -> 0 | C19: =SUMIF(BASE!$B$6:$B$1740,A19,BASE!$F$6:$F$1740) -> 0 | D19: 0 | E19: =COUNTIFS(BASE!$B$6:$B$1740,A19,BASE!$M$6:$M$1740,"SAUVÉ") -> 0 | F19: =COUNTIFS(BASE!$B$6:$B$1740,A19,BASE!$M$6:$M$1740,"CHARGÉ") -> 0 | G19: =COUNTIFS(BASE!$B$6:$B$1740,A19,BASE!$M$6:$M$1740,"NON CHARGÉ") -> 0 | H19: =COUNTIFS(BASE!$B$6:$B$1740,A19,BASE!$M$6:$M$1740,"ANNULÉ") -> 0 | I19: =IFERROR(E19/B19,0) -> 0
B20: =COUNTIF(BASE!$B$6:$B$1740,A20) -> 0 | C20: =SUMIF(BASE!$B$6:$B$1740,A20,BASE!$F$6:$F$1740) -> 0 | D20: 0 | E20: =COUNTIFS(BASE!$B$6:$B$1740,A20,BASE!$M$6:$M$1740,"SAUVÉ") -> 0 | F20: =COUNTIFS(BASE!$B$6:$B$1740,A20,BASE!$M$6:$M$1740,"CHARGÉ") -> 0 | G20: =COUNTIFS(BASE!$B$6:$B$1740,A20,BASE!$M$6:$M$1740,"NON CHARGÉ") -> 0 | H20: =COUNTIFS(BASE!$B$6:$B$1740,A20,BASE!$M$6:$M$1740,"ANNULÉ") -> 0 | I20: =IFERROR(E20/B20,0) -> 0
B21: =COUNTIF(BASE!$B$6:$B$1740,A21) -> 0 | C21: =SUMIF(BASE!$B$6:$B$1740,A21,BASE!$F$6:$F$1740) -> 0 | D21: 0 | E21: =COUNTIFS(BASE!$B$6:$B$1740,A21,BASE!$M$6:$M$1740,"SAUVÉ") -> 0 | F21: =COUNTIFS(BASE!$B$6:$B$1740,A21,BASE!$M$6:$M$1740,"CHARGÉ") -> 0 | G21: =COUNTIFS(BASE!$B$6:$B$1740,A21,BASE!$M$6:$M$1740,"NON CHARGÉ") -> 0 | H21: =COUNTIFS(BASE!$B$6:$B$1740,A21,BASE!$M$6:$M$1740,"ANNULÉ") -> 0 | I21: =IFERROR(E21/B21,0) -> 0
B22: =COUNTIF(BASE!$B$6:$B$1740,A22) -> 0 | C22: =SUMIF(BASE!$B$6:$B$1740,A22,BASE!$F$6:$F$1740) -> 0 | D22: 0 | E22: =COUNTIFS(BASE!$B$6:$B$1740,A22,BASE!$M$6:$M$1740,"SAUVÉ") -> 0 | F22: =COUNTIFS(BASE!$B$6:$B$1740,A22,BASE!$M$6:$M$1740,"CHARGÉ") -> 0 | G22: =COUNTIFS(BASE!$B$6:$B$1740,A22,BASE!$M$6:$M$1740,"NON CHARGÉ") -> 0 | H22: =COUNTIFS(BASE!$B$6:$B$1740,A22,BASE!$M$6:$M$1740,"ANNULÉ") -> 0 | I22: =IFERROR(E22/B22,0) -> 0
B23: =COUNTIF(BASE!$B$6:$B$1740,A23) -> 0 | C23: =SUMIF(BASE!$B$6:$B$1740,A23,BASE!$F$6:$F$1740) -> 0 | D23: 0 | E23: =COUNTIFS(BASE!$B$6:$B$1740,A23,BASE!$M$6:$M$1740,"SAUVÉ") -> 0 | F23: =COUNTIFS(BASE!$B$6:$B$1740,A23,BASE!$M$6:$M$1740,"CHARGÉ") -> 0 | G23: =COUNTIFS(BASE!$B$6:$B$1740,A23,BASE!$M$6:$M$1740,"NON CHARGÉ") -> 0 | H23: =COUNTIFS(BASE!$B$6:$B$1740,A23,BASE!$M$6:$M$1740,"ANNULÉ") -> 0 | I23: =IFERROR(E23/B23,0) -> 0
B24: =COUNTIF(BASE!$B$6:$B$1740,A24) -> 0 | C24: =SUMIF(BASE!$B$6:$B$1740,A24,BASE!$F$6:$F$1740) -> 0 | D24: 0 | E24: =COUNTIFS(BASE!$B$6:$B$1740,A24,BASE!$M$6:$M$1740,"SAUVÉ") -> 0 | F24: =COUNTIFS(BASE!$B$6:$B$1740,A24,BASE!$M$6:$M$1740,"CHARGÉ") -> 0 | G24: =COUNTIFS(BASE!$B$6:$B$1740,A24,BASE!$M$6:$M$1740,"NON CHARGÉ") -> 0 | H24: =COUNTIFS(BASE!$B$6:$B$1740,A24,BASE!$M$6:$M$1740,"ANNULÉ") -> 0 | I24: =IFERROR(E24/B24,0) -> 0
B25: =COUNTIF(BASE!$B$6:$B$1740,A25) -> 0 | C25: =SUMIF(BASE!$B$6:$B$1740,A25,BASE!$F$6:$F$1740) -> 0 | D25: 0 | E25: =COUNTIFS(BASE!$B$6:$B$1740,A25,BASE!$M$6:$M$1740,"SAUVÉ") -> 0 | F25: =COUNTIFS(BASE!$B$6:$B$1740,A25,BASE!$M$6:$M$1740,"CHARGÉ") -> 0 | G25: =COUNTIFS(BASE!$B$6:$B$1740,A25,BASE!$M$6:$M$1740,"NON CHARGÉ") -> 0 | H25: =COUNTIFS(BASE!$B$6:$B$1740,A25,BASE!$M$6:$M$1740,"ANNULÉ") -> 0 | I25: =IFERROR(E25/B25,0) -> 0
B26: =COUNTIF(BASE!$B$6:$B$1740,A26) -> 0 | C26: =SUMIF(BASE!$B$6:$B$1740,A26,BASE!$F$6:$F$1740) -> 0 | D26: 0 | E26: =COUNTIFS(BASE!$B$6:$B$1740,A26,BASE!$M$6:$M$1740,"SAUVÉ") -> 0 | F26: =COUNTIFS(BASE!$B$6:$B$1740,A26,BASE!$M$6:$M$1740,"CHARGÉ") -> 0 | G26: =COUNTIFS(BASE!$B$6:$B$1740,A26,BASE!$M$6:$M$1740,"NON CHARGÉ") -> 0 | H26: =COUNTIFS(BASE!$B$6:$B$1740,A26,BASE!$M$6:$M$1740,"ANNULÉ") -> 0 | I26: =IFERROR(E26/B26,0) -> 0
B27: =COUNTIF(BASE!$B$6:$B$1740,A27) -> 0 | C27: =SUMIF(BASE!$B$6:$B$1740,A27,BASE!$F$6:$F$1740) -> 0 | D27: 0 | E27: =COUNTIFS(BASE!$B$6:$B$1740,A27,BASE!$M$6:$M$1740,"SAUVÉ") -> 0 | F27: =COUNTIFS(BASE!$B$6:$B$1740,A27,BASE!$M$6:$M$1740,"CHARGÉ") -> 0 | G27: =COUNTIFS(BASE!$B$6:$B$1740,A27,BASE!$M$6:$M$1740,"NON CHARGÉ") -> 0 | H27: =COUNTIFS(BASE!$B$6:$B$1740,A27,BASE!$M$6:$M$1740,"ANNULÉ") -> 0 | I27: =IFERROR(E27/B27,0) -> 0
A28: TOTAL | B28: =SUM(B14:B27) -> 302 | C28: =SUM(C14:C27) -> 302 | D28: =SUM(D14:D27) -> 17510 | E28: =SUM(E14:E27) -> 44 | F28: =SUM(F14:F27) -> 82 | G28: =SUM(G14:G27) -> 176 | H28: =SUM(H14:H27) -> 0 | I28: =IFERROR(E28/B28,0) -> 0.14569536
A71: STATUT | B71: DOSSIERS
A72: Chargés | B72: =J6 -> 82
A73: Sauvés | B73: =G6 -> 44
A74: Non chargés | B74: =M6 -> 176
A75: Annulés | B75: =P6 -> 0
A110: TAGS EN DOUBLE — À VÉRIFIER (VRAI DOUBLON · STATUT DIFFÉRENT · LÉGITIME)
A111: ="VRAI DOUBLON : "&COUNTIF(BASE!$R$6:$R$1740,"VRAI DOUBLON")&" • STATUT DIFFÉRENT : "&COUNTIF(BASE!$R$6:$R$1740,"STATUT DIFFÉRENT")&" • LÉGITIME : "&COUNTIF(BASE!$R$6:$R$1740,"LÉGITIME") -> VRAI DOUBLON : 0 • STATUT DIFFÉRENT : 0 • LÉGITIME : 0
A112: CIE | B112: DATE | D112: N° VOL | F112: N° TAG | H112: OCC. | I112: TYPE
A113: =IFERROR(INDEX(BASE!$B$6:$B$1740,MATCH(ROWS($A$113:$A113),BASE!$Q$6:$Q$1740,0)),"") | B113: =IFERROR(INDEX(BASE!$A$6:$A$1740,MATCH(ROWS($A$113:$A113),BASE!$Q$6:$Q$1740,0)),"") | D113: =IFERROR(INDEX(BASE!$C$6:$C$1740,MATCH(ROWS($A$113:$A113),BASE!$Q$6:$Q$1740,0)),"") | F113: =IFERROR(INDEX(BASE!$E$6:$E$1740,MATCH(ROWS($A$113:$A113),BASE!$Q$6:$Q$1740,0)),"") | H113: =IFERROR(INDEX(BASE!$P$6:$P$1740,MATCH(ROWS($A$113:$A113),BASE!$Q$6:$Q$1740,0)),"") | I113: =IFERROR(INDEX(BASE!$R$6:$R$1740,MATCH(ROWS($A$113:$A113),BASE!$Q$6:$Q$1740,0)),"")
A114: =IFERROR(INDEX(BASE!$B$6:$B$1740,MATCH(ROWS($A$113:$A114),BASE!$Q$6:$Q$1740,0)),"") | B114: =IFERROR(INDEX(BASE!$A$6:$A$1740,MATCH(ROWS($A$113:$A114),BASE!$Q$6:$Q$1740,0)),"") | D114: =IFERROR(INDEX(BASE!$C$6:$C$1740,MATCH(ROWS($A$113:$A114),BASE!$Q$6:$Q$1740,0)),"") | F114: =IFERROR(INDEX(BASE!$E$6:$E$1740,MATCH(ROWS($A$113:$A114),BASE!$Q$6:$Q$1740,0)),"") | H114: =IFERROR(INDEX(BASE!$P$6:$P$1740,MATCH(ROWS($A$113:$A114),BASE!$Q$6:$Q$1740,0)),"") | I114: =IFERROR(INDEX(BASE!$R$6:$R$1740,MATCH(ROWS($A$113:$A114),BASE!$Q$6:$Q$1740,0)),"")
A115: =IFERROR(INDEX(BASE!$B$6:$B$1740,MATCH(ROWS($A$113:$A115),BASE!$Q$6:$Q$1740,0)),"") | B115: =IFERROR(INDEX(BASE!$A$6:$A$1740,MATCH(ROWS($A$113:$A115),BASE!$Q$6:$Q$1740,0)),"") | D115: =IFERROR(INDEX(BASE!$C$6:$C$1740,MATCH(ROWS($A$113:$A115),BASE!$Q$6:$Q$1740,0)),"") | F115: =IFERROR(INDEX(BASE!$E$6:$E$1740,MATCH(ROWS($A$113:$A115),BASE!$Q$6:$Q$1740,0)),"") | H115: =IFERROR(INDEX(BASE!$P$6:$P$1740,MATCH(ROWS($A$113:$A115),BASE!$Q$6:$Q$1740,0)),"") | I115: =IFERROR(INDEX(BASE!$R$6:$R$1740,MATCH(ROWS($A$113:$A115),BASE!$Q$6:$Q$1740,0)),"")
A116: =IFERROR(INDEX(BASE!$B$6:$B$1740,MATCH(ROWS($A$113:$A116),BASE!$Q$6:$Q$1740,0)),"") | B116: =IFERROR(INDEX(BASE!$A$6:$A$1740,MATCH(ROWS($A$113:$A116),BASE!$Q$6:$Q$1740,0)),"") | D116: =IFERROR(INDEX(BASE!$C$6:$C$1740,MATCH(ROWS($A$113:$A116),BASE!$Q$6:$Q$1740,0)),"") | F116: =IFERROR(INDEX(BASE!$E$6:$E$1740,MATCH(ROWS($A$113:$A116),BASE!$Q$6:$Q$1740,0)),"") | H116: =IFERROR(INDEX(BASE!$P$6:$P$1740,MATCH(ROWS($A$113:$A116),BASE!$Q$6:$Q$1740,0)),"") | I116: =IFERROR(INDEX(BASE!$R$6:$R$1740,MATCH(ROWS($A$113:$A116),BASE!$Q$6:$Q$1740,0)),"")
A117: =IFERROR(INDEX(BASE!$B$6:$B$1740,MATCH(ROWS($A$113:$A117),BASE!$Q$6:$Q$1740,0)),"") | B117: =IFERROR(INDEX(BASE!$A$6:$A$1740,MATCH(ROWS($A$113:$A117),BASE!$Q$6:$Q$1740,0)),"") | D117: =IFERROR(INDEX(BASE!$C$6:$C$1740,MATCH(ROWS($A$113:$A117),BASE!$Q$6:$Q$1740,0)),"") | F117: =IFERROR(INDEX(BASE!$E$6:$E$1740,MATCH(ROWS($A$113:$A117),BASE!$Q$6:$Q$1740,0)),"") | H117: =IFERROR(INDEX(BASE!$P$6:$P$1740,MATCH(ROWS($A$113:$A117),BASE!$Q$6:$Q$1740,0)),"") | I117: =IFERROR(INDEX(BASE!$R$6:$R$1740,MATCH(ROWS($A$113:$A117),BASE!$Q$6:$Q$1740,0)),"")
A118: =IFERROR(INDEX(BASE!$B$6:$B$1740,MATCH(ROWS($A$113:$A118),BASE!$Q$6:$Q$1740,0)),"") | B118: =IFERROR(INDEX(BASE!$A$6:$A$1740,MATCH(ROWS($A$113:$A118),BASE!$Q$6:$Q$1740,0)),"") | D118: =IFERROR(INDEX(BASE!$C$6:$C$1740,MATCH(ROWS($A$113:$A118),BASE!$Q$6:$Q$1740,0)),"") | F118: =IFERROR(INDEX(BASE!$E$6:$E$1740,MATCH(ROWS($A$113:$A118),BASE!$Q$6:$Q$1740,0)),"") | H118: =IFERROR(INDEX(BASE!$P$6:$P$1740,MATCH(ROWS($A$113:$A118),BASE!$Q$6:$Q$1740,0)),"") | I118: =IFERROR(INDEX(BASE!$R$6:$R$1740,MATCH(ROWS($A$113:$A118),BASE!$Q$6:$Q$1740,0)),"")
A119: =IFERROR(INDEX(BASE!$B$6:$B$1740,MATCH(ROWS($A$113:$A119),BASE!$Q$6:$Q$1740,0)),"") | B119: =IFERROR(INDEX(BASE!$A$6:$A$1740,MATCH(ROWS($A$113:$A119),BASE!$Q$6:$Q$1740,0)),"") | D119: =IFERROR(INDEX(BASE!$C$6:$C$1740,MATCH(ROWS($A$113:$A119),BASE!$Q$6:$Q$1740,0)),"") | F119: =IFERROR(INDEX(BASE!$E$6:$E$1740,MATCH(ROWS($A$113:$A119),BASE!$Q$6:$Q$1740,0)),"") | H119: =IFERROR(INDEX(BASE!$P$6:$P$1740,MATCH(ROWS($A$113:$A119),BASE!$Q$6:$Q$1740,0)),"") | I119: =IFERROR(INDEX(BASE!$R$6:$R$1740,MATCH(ROWS($A$113:$A119),BASE!$Q$6:$Q$1740,0)),"")
A120: =IFERROR(INDEX(BASE!$B$6:$B$1740,MATCH(ROWS($A$113:$A120),BASE!$Q$6:$Q$1740,0)),"") | B120: =IFERROR(INDEX(BASE!$A$6:$A$1740,MATCH(ROWS($A$113:$A120),BASE!$Q$6:$Q$1740,0)),"") | D120: =IFERROR(INDEX(BASE!$C$6:$C$1740,MATCH(ROWS($A$113:$A120),BASE!$Q$6:$Q$1740,0)),"") | F120: =IFERROR(INDEX(BASE!$E$6:$E$1740,MATCH(ROWS($A$113:$A120),BASE!$Q$6:$Q$1740,0)),"") | H120: =IFERROR(INDEX(BASE!$P$6:$P$1740,MATCH(ROWS($A$113:$A120),BASE!$Q$6:$Q$1740,0)),"") | I120: =IFERROR(INDEX(BASE!$R$6:$R$1740,MATCH(ROWS($A$113:$A120),BASE!$Q$6:$Q$1740,0)),"")
A121: =IFERROR(INDEX(BASE!$B$6:$B$1740,MATCH(ROWS($A$113:$A121),BASE!$Q$6:$Q$1740,0)),"") | B121: =IFERROR(INDEX(BASE!$A$6:$A$1740,MATCH(ROWS($A$113:$A121),BASE!$Q$6:$Q$1740,0)),"") | D121: =IFERROR(INDEX(BASE!$C$6:$C$1740,MATCH(ROWS($A$113:$A121),BASE!$Q$6:$Q$1740,0)),"") | F121: =IFERROR(INDEX(BASE!$E$6:$E$1740,MATCH(ROWS($A$113:$A121),BASE!$Q$6:$Q$1740,0)),"") | H121: =IFERROR(INDEX(BASE!$P$6:$P$1740,MATCH(ROWS($A$113:$A121),BASE!$Q$6:$Q$1740,0)),"") | I121: =IFERROR(INDEX(BASE!$R$6:$R$1740,MATCH(ROWS($A$113:$A121),BASE!$Q$6:$Q$1740,0)),"")
...

Sheet DOSSIERS
A1: FLUX BAGAGES — DOSSIERS — EI — AER LINGUS
A3: COMPTE RENDU DE SUPERVISION • SEPTEMBRE 2026 • EI — AER LINGUS
A4: FILTRES EXCEL ▼ • Sélectionnez DATE, CIE, N° VOL, N° TAG ou STATUT dans les en-têtes. Toutes les journées sont regroupées ici.
A5: DATE | B5: CIE | C5: N° VOL | D5: HEURE DÉPART | E5: N° TAG | F5: NOMBRE BAGAGES | G5: VOL APPORT | H5: HEURE ARRIVÉE | I5: LOCALISATION | J5: REMARQUES | K5: ANOMALIE | L5: COMMENTAIRE/ACTION | M5: STATUT | N5: FAULT STATION
A6: 46266 | B6: EI | C6: EI527 | D6: 17H00 | E6: EI129754 | F6: 1 | G6: RUSH | I6: AUCUNE TRACE | K6: BSM ONLY | L6: APPEL DIRBY T1 A 16H41 MAIS INJOIGNABLE | M6: NON CHARGÉ | N6: 21 - Bag left at station origin / correctly labelled
A7: 46266 | B7: EI | C7: EI527 | D7: 17H00 | E7: EI129755 | F7: 1 | G7: RUSH | I7: AUCUNE TRACE | K7: BSM ONLY | L7: APPEL DIRBY T1 A 16H41 MAIS INJOIGNABLE | M7: NON CHARGÉ | N7: 21 - Bag left at station origin / correctly labelled
A8: 46266 | B8: EI | C8: EI527 | D8: 17H00 | E8: EI129756 | F8: 1 | G8: RUSH | I8: AUCUNE TRACE | K8: BSM ONLY | L8: APPEL DIRBY T1 A 16H41 MAIS INJOIGNABLE | M8: NON CHARGÉ | N8: 21 - Bag left at station origin / correctly labelled
A9: 46266 | B9: EI | C9: EI527 | D9: 17H00 | E9: EI129757 | F9: 1 | G9: RUSH | I9: AUCUNE TRACE | K9: BSM ONLY | L9: APPEL DIRBY T1 A 16H41 MAIS INJOIGNABLE | M9: NON CHARGÉ | N9: 21 - Bag left at station origin / correctly labelled
A10: 46267 | B10: EI | C10: EI521 | D10: 10H20 | E10: SQ658922 | F10: 1 | G10: NON NOTIFIE | I10: PAS DE TRACE | K10: PAS DE TRACE | L10: 09H41 : NEG DS TOUS SYSTEMES/J+1 MISCNX A SIN /RECU SUR LE SQ338/02SEP LOCALISE AN SLB 21H41 /DUBEI28745 FO EI523/03SEP | M10: NON CHARGÉ | N10: 56 - Online - own carrier - MCT not available
A11: 46267 | B11: EI | C11: EI523 | D11: 11H15 | E11: EI129848 | F11: 1 | G11: LOCAL/RUSH | I11: T1 HORS FORMAT | L11: 10H37 : APPEL HORS FORMAT PUIS GALERIE T1 - BAG SERA DEPOSE SS BORD DES QU IL SERA TROUVE - PEUT ETRE CHARGE SS SCAN/J+1 DOSSIER TOUJOUR OUVERT | M11: NON CHARGÉ | N11: 21 - Bag left at station origin / correctly labelled
A12: 46267 | B12: EI | C12: EI525 | D12: 13H15 | E12: EI215344 | F12: 1 | G12: LOCAL | I12: PAS DE LOC | K12: PAS DE LOC | L12: 7KG PROBABLEMENT PRIS EN PORTE | M12: CHARGÉ
A13: 46267 | B13: EI | C13: EI525 | D13: 13H15 | E13: EI215655 | F13: 1 | G13: LOCAL | I13: PAS DE LOC | K13: CYNO OK 13H22 | L13: RETARD TRAITEMENT/J+1 DUBEI28761 EN ATTENTE DE FWD | M13: NON CHARGÉ | N13: 64 - Unserviceable equipment / belt / sortation system
A14: 46267 | B14: EI | C14: EI529 | D14: 21H55 | E14: EI129974 | F14: 1 | G14: RUSH | I14: PAS DE TRACE | J14: BAG SOUTE S/SCAN | K14: BSM ONLY | L14: APPEL DIRBY T1 A 20H32 ET DEMANDE DE FAIRE LE NECESSAIRE/RUSH PAS EN GALERIE DOIT VERIF AVEC SES COLLEGUES EN SLB | M14: CHARGÉ
A15: 46268 | B15: EI | C15: EI909 | D15: 11H10 | E15: EI217604 | F15: 1 | G15: LOCAL | I15: JETEE T1 09H06 | K15: CLASSE NON CORRECTE | L15: BAG CHARGE EN CONTENANT AKH67388EI/ J+1 SNNEI76763 EN ATTENTE DE FWD | M15: NON CHARGÉ | N15: 18 - Bag not authorized to load
A16: 46268 | B16: EI | C16: EI909 | D16: 11H10 | E16: EI217607 | F16: 1 | G16: LOCAL | I16: T1 ARRIVEE 2 10H45 | L16: BAG DECHARGE DE CONTENANT AKH67388EI ET DEPOSE T1 ARRIVEE/ J+1 SNNEI76763 EN ATTENTE DE FWD | M16: NON CHARGÉ | N16: 18 - Bag not authorized to load
A17: 46268 | B17: EI | C17: EI909 | D17: 11H10 | E17: MH871123 | F17: 1 | G17: MH021 | H17: 06H21 | I17: T1 ARRIVEE 2 10H45 | K17: ARRIVEE TARDIVE | L17: DECHARGE DE NAVETTE 08H22 SAT 1 / BAG ENVOYE SOUS BORD MAIS REFUSE /ENOIYE JETEE T1 10H44/RETOUR LL ET DEPOSE T1 ARRIVEE 10H44/ J+1 SNNEI76762 EN ATTENTE DE FWD | M17: NON CHARGÉ | N17: 18 - Bag not authorized to load
A18: 46268 | B18: EI | C18: EI523 | D18: 11H15 | E18: EI218542 | F18: 1 | G18: LOCAL | I18: T1 EJECTION 10H34 | L18: EJECTION TARDIVE/ J+1 DUBEI28845 EN ATTENTE DE FWD | M18: NON CHARGÉ | N18: 64 - Unserviceable equipment / belt / sortation system
A19: 46268 | B19: EI | C19: EI523 | D19: 11H15 | E19: EI218708 | F19: 1 | G19: LOCAL | I19: JETEE T1 11H41 | K19: EJECTION TARDIVE | L19: EJECTION TARDIVE BAG SCANNE SUR LE MAUVAIS VOL /J+1 DUBEI28845 EN ATTENTE DE FWD | M19: NON CHARGÉ | N19: 64 - Unserviceable equipment / belt / sortation system
A20: 46268 | B20: EI | C20: EI523 | D20: 11H15 | E20: UA238710 | F20: 1 | G20: UA915 | H20: 07H49 | I20: SAT 1 /08H09 | K20: EJECTION TARDIVE | L20: EJETION JETEE T1 A 10H44/DEPOSE T1 ARRIVEE LL/ J+1 DUBEI28848 | M20: NON CHARGÉ | N20: 64 - Unserviceable equipment / belt / sortation system
A21: 46268 | B21: EI | C21: EI523 | D21: 11H15 | E21: UA189600 | F21: 1 | G21: UA915 | H21: 07H49 | I21: JETEE T1 10H43 | K21: EJECTION TARDIVE | L21: EJETION JETEE T1 A 10H44/DEPOSE T1 ARRIVEE LL/ J+1 DUBEI28848 | M21: NON CHARGÉ | N21: 64 - Unserviceable equipment / belt / sortation system
A22: 46268 | B22: EI | C22: EI523 | D22: 11H15 | E22: UA032310 | F22: 1 | G22: UA915 | H22: 07H49 | I22: SAT 1 /08H09 | K22: EJECTION TARDIVE | L22: EJETION JETEE T1 A 10H44/DEPOSE T1 ARRIVEE LL/ J+1 DUBEI28848 | M22: NON CHARGÉ | N22: 64 - Unserviceable equipment / belt / sortation system
A23: 46268 | B23: EI | C23: EI523 | D23: 11H15 | E23: MH870031 | F23: 1 | G23: MH021 | H23: 06H21 | I23: JETEE T1 10GH44 | K23: EJECTION TARDIVE | L23: EJETION JETEE T1 A 10H44/DEPOSE T1 ARRIVEE LL/ J+1 DUBEI28855 | M23: NON CHARGÉ | N23: 64 - Unserviceable equipment / belt / sortation system
A24: 46268 | B24: EI | C24: EI523 | D24: 11H15 | E24: MH869996 | F24: 1 | G24: MH021 | H24: 06H21 | I24: JETEE T1 10H44 | K24: EJECTION TARDIVE | L24: EJETION JETEE T1 A 10H44/DEPOSE T1 ARRIVEE LL/ J+1 DUBEI28855 | M24: NON CHARGÉ | N24: 64 - Unserviceable equipment / belt / sortation system
A25: 46268 | B25: EI | C25: EI523 | D25: 11H15 | E25: MH869978 | F25: 1 | G25: MH021 | H25: 06H21 | I25: JETEE T1 10H44 | K25: EJECTION TARDIVE | L25: EJETION JETEE T1 A 10H44/DEPOSE T1 ARRIVEE LL/ J+1 DUBEI28855 | M25: NON CHARGÉ | N25: 64 - Unserviceable equipment / belt / sortation system
A26: 46268 | B26: EI | C26: EI523 | D26: 11H15 | E26: MH869966 | F26: 1 | G26: MH021 | H26: 06H21 | I26: JETEE T1 10H44 | K26: EJECTION TARDIVE | L26: EJETION JETEE T1 A 10H44/DEPOSE T1 ARRIVEE LL/ J+1 DUBEI28855 | M26: NON CHARGÉ | N26: 64 - Unserviceable equipment / belt / sortation system
A27: 46268 | B27: EI | C27: EI523 | D27: 11H15 | E27: MH872323 | F27: 1 | G27: MH021 | H27: 06H21 | I27: BSM ONLY | K27: PAS DE TRACE | L27: EJETION JETEE T1 A 10H44/DEPOSE T1 ARRIVEE LL/ J+1 DUBEI28855 | M27: NON CHARGÉ | N27: 64 - Unserviceable equipment / belt / sortation system
A28: 46268 | B28: EI | C28: EI523 | D28: 11H15 | E28: EI218711 | F28: 1 | G28: LOCAL | I28: JETEE T1 11H42 | K28: EJECTION TARDIVE | L28: BAG SCANNE SUR UN AUTRE VOL EI525/ J+1 DUBEI28841 | M28: NON CHARGÉ | N28: 66- responsibility airport services
A29: 46268 | B29: EI | C29: EI523 | D29: 11H15 | E29: AF155186 | F29: 1 | G29: AF453 | H29: 07H05 | I29: JETEE T1 11H55 | K29: EJECTION TARDIVE | L29: BAG SCANNE SUR UN AUTRE VOL EI525/ J+1 DUBEI28857 | M29: NON CHARGÉ | N29: 66- responsibility airport services
A30: 46268 | B30: EI | C30: EI523 | D30: 11H15 | E30: AC574766 | F30: 1 | G30: UA915 | H30: 07H49 | I30: BSM ONLY | K30: PAS DE TRACE | L30: VU EN REQUETEUR/PAS DE TRACE A CDG/ MICNX IAD J+1 DUBEI28847 FO UA915/02SEP/EI521/03SEP NON RECU | M30: NON CHARGÉ | N30: 56 - Online - own carrier - MCT not available
A31: 46268 | B31: EI | C31: EI523 | D31: 11H15 | E31: MH872673 | F31: 1 | G31: MH021 | H31: 06H21 | I31: BSM ONLY | K31: PAS DE TRACE | L31: VU EN REQUETEUR/PAS DE TRACE A CDG/ J+1 DUBEI28842 | M31: NON CHARGÉ | N31: 64 - Unserviceable equipment / belt / sortation system
A32: 46268 | B32: EI | C32: EI523 | D32: 11H15 | E32: UA015580 | F32: 1 | G32: UA915 | H32: 07H49 | I32: BSM ONLY | J32: HBAG | K32: PAS DE TRACE | L32: VU EN REQUETEUR/PAS DE TRACE A CDG/ J+1 PAS DE DOSSIER OUVERT AVEC CE TAG | M32: CHARGÉ
A33: 46268 | B33: EI | C33: EI523 | D33: 11H15 | E33: UA879071 | F33: 1 | G33: UA915 | H33: 07H49 | I33: BSM ONLY | K33: PAS DE TRACE | L33: VU EN REQUETEUR/PAS DE TRACE A CDG MISCNX AT IAD / J+1 DUBEI28843 FO UA310/05SEP | M33: NON CHARGÉ | N33: 56 - Online - own carrier - MCT not available
A34: 46268 | B34: EI | C34: EI525 | D34: 13H15 | E34: EI218815 | F34: 1 | G34: LOCAL | I34: BSM ONLY | J34: STRL | L34: STROLLER | M34: CHARGÉ
A35: 46268 | B35: EI | C35: EI523 | D35: 16H30 | E35: EI219420 | F35: 1 | G35: LOCAL | I35: BSM ONLY | J35: WCH | K35: PAS DE TRACE | L35: WCHR/APPEL LEAD EI A 16H30/APPELE LE COORDO A SON TOUR/ASSURE QUE LA CHAISE A ÉTÉ CHARGEE MAIS PAS SCANNE/SCANNE MANUELLEMENT APRES LE DEP | M35: SAUVÉ
A36: 46268 | B36: EI | C36: EI523 | D36: 21H55 | E36: EI130152 | F36: 1 | G36: RUSH | I36: AUCUNE TRACE | K36: BSM ONLY 16H27 | L36: APPEL DIRBY T1 A 21H07/DIT QUE LE RUSH A BIEN ÉTÉ ENVOYE MALGRE LE MANQUE DE TRACE/APPEL SUP GALERIE T1 /RUSH EN GAL MAIS PAS SCANNE | M36: SAUVÉ
A37: 46268 | B37: EI | C37: EI523 | D37: 21H55 | E37: EI130151 | F37: 1 | G37: RUSH | I37: T1 CYNO MJ90 21H09 | K37: PAS DE MVT | L37: APPEL GALERIE T1 A 21H12 ET SIGNALE POUR LE RECUPERER | M37: SAUVÉ
A38: 46269 | B38: EI | C38: EI521 | D38: 10H20 | E38: AF256896 | F38: 1 | G38: AF4199 | H38: 08H25 | I38: WJ43 09H53 | K38: SHORT CONNEX | L38: APPEL GALERIE T1 POUR ENVOIE SOUS BORD | M38: SAUVÉ
A39: 46269 | B39: EI | C39: EI521 | D39: 10H20 | E39: BR703261 | F39: 1 | H39: 08H25 | I39: REBUT T1 | L39: APPEL GALERIE T1 POUR ENVOIE SOUS BORD A 09H40 PUIS LOCALISE AU REBUT T1 A 09H53 - AHLDUBEI28991 PAS DE RUSH PREVU A J+1 | M39: NON CHARGÉ | N39: 66- responsibility airport services
A40: 46269 | B40: EI | C40: EI521 | D40: 10H20 | E40: AF245898 | F40: 1 | G40: AF4199 | H40: 08H25 | I40: DECHARGE AU SAT1 A 10H29 | K40: SHORT CONNEX | L40: ARRIVE AU SAT T1 A 10H29 TROP TARD POUR CHARGEMENT - AHLDUBEI28990 PAS DE RUSH PREVU A J+1 | M40: NON CHARGÉ | N40: 52 - Interline MCT not available ( MCT initialement non respecté)
A41: 46269 | B41: EI | C41: EI521 | D41: 10H20 | E41: AF256220 | F41: 1 | G41: AF4199 | H41: 08H25 | I41: DECHARGE AU SAT1 A 10H29 | K41: SHORT CONNEX | L41: ARRIVE AU SAT T1 A 10H29 TROP TARD POUR CHARGEMENT - AHLDUBEI28993 PAS DE RUSH PREVU A J+1 | M41: NON CHARGÉ | N41: 52 - Interline MCT not available ( MCT initialement non respecté)
...

Sheet JOUR PAR JOUR
A1: FLUX BAGAGES — JOUR PAR JOUR — EI — AER LINGUS
A3: COMPTE RENDU DE SUPERVISION • SEPTEMBRE 2026 • EI — AER LINGUS
A5: DATE AFFICHÉE ▶ | C5: 46267 | AA5: 46266
AA6: 46267
A7: RÉCAPITULATIF JOURNALIER • Changer la date en C5 | I7: DOSSIERS DU JOUR • Filtrer la date dans DOSSIERS pour consulter les détails | AA7: 46268
A8: CIE | B8: BAG. ATTENDUS | C8: DOSSIERS | D8: SAUVÉS | E8: CHARGÉS | F8: NON CHARGÉS | G8: ANNULÉS | I8: Le récapitulatif se met à jour avec la date C5. Pour afficher et imprimer les dossiers détaillés du jour, utilisez le filtre DATE de la feuille DOSSIERS. | AA8: 46269
A9: EI | B9: =IFERROR(INDEX('SYNTHÈSE PAR DATE'!$I$6:$I$36,MATCH($C$5,'SYNTHÈSE PAR DATE'!$A$6:$A$36,0)),0) -> 371 | C9: =COUNTIFS(BASE!$A$6:$A$1740,$C$5,BASE!$B$6:$B$1740,$A9) -> 5 | D9: =COUNTIFS(BASE!$A$6:$A$1740,$C$5,BASE!$B$6:$B$1740,$A9,BASE!$M$6:$M$1740,"SAUVÉ") -> 0 | E9: =COUNTIFS(BASE!$A$6:$A$1740,$C$5,BASE!$B$6:$B$1740,$A9,BASE!$M$6:$M$1740,"CHARGÉ") -> 2 | F9: =COUNTIFS(BASE!$A$6:$A$1740,$C$5,BASE!$B$6:$B$1740,$A9,BASE!$M$6:$M$1740,"NON CHARGÉ") -> 3 | G9: =COUNTIFS(BASE!$A$6:$A$1740,$C$5,BASE!$B$6:$B$1740,$A9,BASE!$M$6:$M$1740,"ANNULÉ") -> 0 | AA9: 46270
A10: TOTAL JOUR | B10: =SUM(B9:B9) -> 371 | C10: =SUM(C9:C9) -> 5 | D10: =SUM(D9:D9) -> 0 | E10: =SUM(E9:E9) -> 2 | F10: =SUM(F9:F9) -> 3 | G10: =SUM(G9:G9) -> 0
AA24: 46285
AA25: 46286
AA26: 46287
AA27: 46288
AA28: 46289
AA29: 46290
AA30: 46291
AA31: 46292
AA32: 46293
AA33: 46294
AA34: 46295

Sheet SYNTHÈSE PAR DATE
A1: FLUX BAGAGES — SYNTHÈSE PAR DATE — EI — AER LINGUS
A3: COMPTE RENDU DE SUPERVISION • SEPTEMBRE 2026 • EI — AER LINGUS
A4: SUIVI JOURNALIER • Calculé à partir de la BASE | I4: BAGAGES ATTENDUS PAR COMPAGNIE • Données source conservées
A5: DATE | B5: DOSSIERS | C5: BAGAGES TRAITÉS | D5: BAGAGES ATTENDUS | E5: SAUVÉS | F5: CHARGÉS | G5: NON CHARGÉS | H5: ANNULÉS | I5: EI
A6: 46266 | B6: =COUNTIF(BASE!$A$6:$A$1740,A6) -> 4 | C6: =SUMIF(BASE!$A$6:$A$1740,A6,BASE!$F$6:$F$1740) -> 4 | D6: =SUM(I6:V6) -> 402 | E6: =COUNTIFS(BASE!$A$6:$A$1740,A6,BASE!$M$6:$M$1740,"SAUVÉ") -> 0 | F6: =COUNTIFS(BASE!$A$6:$A$1740,A6,BASE!$M$6:$M$1740,"CHARGÉ") -> 0 | G6: =COUNTIFS(BASE!$A$6:$A$1740,A6,BASE!$M$6:$M$1740,"NON CHARGÉ") -> 4 | H6: =COUNTIFS(BASE!$A$6:$A$1740,A6,BASE!$M$6:$M$1740,"ANNULÉ") -> 0 | I6: 402
A7: 46267 | B7: =COUNTIF(BASE!$A$6:$A$1740,A7) -> 5 | C7: =SUMIF(BASE!$A$6:$A$1740,A7,BASE!$F$6:$F$1740) -> 5 | D7: =SUM(I7:V7) -> 371 | E7: =COUNTIFS(BASE!$A$6:$A$1740,A7,BASE!$M$6:$M$1740,"SAUVÉ") -> 0 | F7: =COUNTIFS(BASE!$A$6:$A$1740,A7,BASE!$M$6:$M$1740,"CHARGÉ") -> 2 | G7: =COUNTIFS(BASE!$A$6:$A$1740,A7,BASE!$M$6:$M$1740,"NON CHARGÉ") -> 3 | H7: =COUNTIFS(BASE!$A$6:$A$1740,A7,BASE!$M$6:$M$1740,"ANNULÉ") -> 0 | I7: 371
A8: 46268 | B8: =COUNTIF(BASE!$A$6:$A$1740,A8) -> 23 | C8: =SUMIF(BASE!$A$6:$A$1740,A8,BASE!$F$6:$F$1740) -> 23 | D8: =SUM(I8:V8) -> 501 | E8: =COUNTIFS(BASE!$A$6:$A$1740,A8,BASE!$M$6:$M$1740,"SAUVÉ") -> 3 | F8: =COUNTIFS(BASE!$A$6:$A$1740,A8,BASE!$M$6:$M$1740,"CHARGÉ") -> 2 | G8: =COUNTIFS(BASE!$A$6:$A$1740,A8,BASE!$M$6:$M$1740,"NON CHARGÉ") -> 18 | H8: =COUNTIFS(BASE!$A$6:$A$1740,A8,BASE!$M$6:$M$1740,"ANNULÉ") -> 0 | I8: 501
A9: 46269 | B9: =COUNTIF(BASE!$A$6:$A$1740,A9) -> 10 | C9: =SUMIF(BASE!$A$6:$A$1740,A9,BASE!$F$6:$F$1740) -> 10 | D9: =SUM(I9:V9) -> 521 | E9: =COUNTIFS(BASE!$A$6:$A$1740,A9,BASE!$M$6:$M$1740,"SAUVÉ") -> 2 | F9: =COUNTIFS(BASE!$A$6:$A$1740,A9,BASE!$M$6:$M$1740,"CHARGÉ") -> 2 | G9: =COUNTIFS(BASE!$A$6:$A$1740,A9,BASE!$M$6:$M$1740,"NON CHARGÉ") -> 6 | H9: =COUNTIFS(BASE!$A$6:$A$1740,A9,BASE!$M$6:$M$1740,"ANNULÉ") -> 0 | I9: 521
A10: 46270 | B10: =COUNTIF(BASE!$A$6:$A$1740,A10) -> 23 | C10: =SUMIF(BASE!$A$6:$A$1740,A10,BASE!$F$6:$F$1740) -> 23 | D10: =SUM(I10:V10) -> 567 | E10: =COUNTIFS(BASE!$A$6:$A$1740,A10,BASE!$M$6:$M$1740,"SAUVÉ") -> 4 | F10: =COUNTIFS(BASE!$A$6:$A$1740,A10,BASE!$M$6:$M$1740,"CHARGÉ") -> 1 | G10: =COUNTIFS(BASE!$A$6:$A$1740,A10,BASE!$M$6:$M$1740,"NON CHARGÉ") -> 18 | H10: =COUNTIFS(BASE!$A$6:$A$1740,A10,BASE!$M$6:$M$1740,"ANNULÉ") -> 0 | I10: 567
A11: 46271 | B11: =COUNTIF(BASE!$A$6:$A$1740,A11) -> 12 | C11: =SUMIF(BASE!$A$6:$A$1740,A11,BASE!$F$6:$F$1740) -> 12 | D11: =SUM(I11:V11) -> 743 | E11: =COUNTIFS(BASE!$A$6:$A$1740,A11,BASE!$M$6:$M$1740,"SAUVÉ") -> 0 | F11: =COUNTIFS(BASE!$A$6:$A$1740,A11,BASE!$M$6:$M$1740,"CHARGÉ") -> 2 | G11: =COUNTIFS(BASE!$A$6:$A$1740,A11,BASE!$M$6:$M$1740,"NON CHARGÉ") -> 10 | H11: =COUNTIFS(BASE!$A$6:$A$1740,A11,BASE!$M$6:$M$1740,"ANNULÉ") -> 0 | I11: 743
A12: 46272 | B12: =COUNTIF(BASE!$A$6:$A$1740,A12) -> 7 | C12: =SUMIF(BASE!$A$6:$A$1740,A12,BASE!$F$6:$F$1740) -> 7 | D12: =SUM(I12:V12) -> 599 | E12: =COUNTIFS(BASE!$A$6:$A$1740,A12,BASE!$M$6:$M$1740,"SAUVÉ") -> 0 | F12: =COUNTIFS(BASE!$A$6:$A$1740,A12,BASE!$M$6:$M$1740,"CHARGÉ") -> 3 | G12: =COUNTIFS(BASE!$A$6:$A$1740,A12,BASE!$M$6:$M$1740,"NON CHARGÉ") -> 4 | H12: =COUNTIFS(BASE!$A$6:$A$1740,A12,BASE!$M$6:$M$1740,"ANNULÉ") -> 0 | I12: 599
A13: 46273 | B13: =COUNTIF(BASE!$A$6:$A$1740,A13) -> 7 | C13: =SUMIF(BASE!$A$6:$A$1740,A13,BASE!$F$6:$F$1740) -> 7 | D13: =SUM(I13:V13) -> 489 | E13: =COUNTIFS(BASE!$A$6:$A$1740,A13,BASE!$M$6:$M$1740,"SAUVÉ") -> 2 | F13: =COUNTIFS(BASE!$A$6:$A$1740,A13,BASE!$M$6:$M$1740,"CHARGÉ") -> 3 | G13: =COUNTIFS(BASE!$A$6:$A$1740,A13,BASE!$M$6:$M$1740,"NON CHARGÉ") -> 2 | H13: =COUNTIFS(BASE!$A$6:$A$1740,A13,BASE!$M$6:$M$1740,"ANNULÉ") -> 0 | I13: 489
A14: 46274 | B14: =COUNTIF(BASE!$A$6:$A$1740,A14) -> 20 | C14: =SUMIF(BASE!$A$6:$A$1740,A14,BASE!$F$6:$F$1740) -> 20 | D14: =SUM(I14:V14) -> 592 | E14: =COUNTIFS(BASE!$A$6:$A$1740,A14,BASE!$M$6:$M$1740,"SAUVÉ") -> 2 | F14: =COUNTIFS(BASE!$A$6:$A$1740,A14,BASE!$M$6:$M$1740,"CHARGÉ") -> 4 | G14: =COUNTIFS(BASE!$A$6:$A$1740,A14,BASE!$M$6:$M$1740,"NON CHARGÉ") -> 14 | H14: =COUNTIFS(BASE!$A$6:$A$1740,A14,BASE!$M$6:$M$1740,"ANNULÉ") -> 0 | I14: 592
A15: 46275 | B15: =COUNTIF(BASE!$A$6:$A$1740,A15) -> 13 | C15: =SUMIF(BASE!$A$6:$A$1740,A15,BASE!$F$6:$F$1740) -> 13 | D15: =SUM(I15:V15) -> 551 | E15: =COUNTIFS(BASE!$A$6:$A$1740,A15,BASE!$M$6:$M$1740,"SAUVÉ") -> 4 | F15: =COUNTIFS(BASE!$A$6:$A$1740,A15,BASE!$M$6:$M$1740,"CHARGÉ") -> 2 | G15: =COUNTIFS(BASE!$A$6:$A$1740,A15,BASE!$M$6:$M$1740,"NON CHARGÉ") -> 7 | H15: =COUNTIFS(BASE!$A$6:$A$1740,A15,BASE!$M$6:$M$1740,"ANNULÉ") -> 0 | I15: 551
A16: 46276 | B16: =COUNTIF(BASE!$A$6:$A$1740,A16) -> 4 | C16: =SUMIF(BASE!$A$6:$A$1740,A16,BASE!$F$6:$F$1740) -> 4 | D16: =SUM(I16:V16) -> 546 | E16: =COUNTIFS(BASE!$A$6:$A$1740,A16,BASE!$M$6:$M$1740,"SAUVÉ") -> 0 | F16: =COUNTIFS(BASE!$A$6:$A$1740,A16,BASE!$M$6:$M$1740,"CHARGÉ") -> 1 | G16: =COUNTIFS(BASE!$A$6:$A$1740,A16,BASE!$M$6:$M$1740,"NON CHARGÉ") -> 3 | H16: =COUNTIFS(BASE!$A$6:$A$1740,A16,BASE!$M$6:$M$1740,"ANNULÉ") -> 0 | I16: 546
A17: 46277 | B17: =COUNTIF(BASE!$A$6:$A$1740,A17) -> 7 | C17: =SUMIF(BASE!$A$6:$A$1740,A17,BASE!$F$6:$F$1740) -> 7 | D17: =SUM(I17:V17) -> 576 | E17: =COUNTIFS(BASE!$A$6:$A$1740,A17,BASE!$M$6:$M$1740,"SAUVÉ") -> 1 | F17: =COUNTIFS(BASE!$A$6:$A$1740,A17,BASE!$M$6:$M$1740,"CHARGÉ") -> 1 | G17: =COUNTIFS(BASE!$A$6:$A$1740,A17,BASE!$M$6:$M$1740,"NON CHARGÉ") -> 5 | H17: =COUNTIFS(BASE!$A$6:$A$1740,A17,BASE!$M$6:$M$1740,"ANNULÉ") -> 0 | I17: 576
... A35: 46295 | B35: =COUNTIF(BASE!$A$6:$A$1740,A35) -> 8 | C35: =SUMIF(BASE!$A$6:$A$1740,A35,BASE!$F$6:$F$1740) -> 8 | D35: =SUM(I35:V35) -> 535 | E35: =COUNTIFS(BASE!$A$6:$A$1740,A35,BASE!$M$6:$M$1740,"SAUVÉ") -> 2 | F35: =COUNTIFS(BASE!$A$6:$A$1740,A35,BASE!$M$6:$M$1740,"CHARGÉ") -> 5 | G35: =COUNTIFS(BASE!$A$6:$A$1740,A35,BASE!$M$6:$M$1740,"NON CHARGÉ") -> 1 | H35: =COUNTIFS(BASE!$A$6:$A$1740,A35,BASE!$M$6:$M$1740,"ANNULÉ") -> 0 | I35: 535
A36: TOTAL | B36: =SUM(B6:B35) -> 302 | C36: =SUM(C6:C35) -> 302 | D36: =SUM(D6:D35) -> 17510 | E36: =SUM(E6:E35) -> 44 | F36: =SUM(F6:F35) -> 82 | G36: =SUM(G6:G35) -> 176 | H36: =SUM(H6:H35) -> 0 | I36: =SUM(I6:I35) -> 17510

Sheet BASE
A1: FLUX BAGAGES — BASE — EI — AER LINGUS | AZ1: STATUT | BA1: DOSSIERS
AZ2: SAUVÉS | BA2: =RÉCAPITULATIF!G6 -> 44
A3: COMPTE RENDU DE SUPERVISION • SEPTEMBRE 2026 • EI — AER LINGUS | AZ3: CHARGÉS | BA3: =RÉCAPITULATIF!J6 -> 82
A4: SOURCE DES DONNÉES • Valeurs du fichier transmis, heures normalisées et préfixes de vol affichés | AZ4: NON CHARGÉS | BA4: =RÉCAPITULATIF!M6 -> 176
A5: DATE | B5: CIE | C5: N° VOL | D5: HEURE DÉPART | E5: N° TAG | F5: NOMBRE BAGAGES | G5: VOL APPORT | H5: HEURE ARRIVÉE | I5: LOCALISATION | J5: REMARQUES | K5: ANOMALIE | L5: COMMENTAIRE/ACTION | M5: STATUT | N5: FAULT STATION | P5: OCCURRENCES TAG | Q5: RANG DOUBLON | R5: TYPE DOUBLON | AZ5: ANNULÉS | BA5: =RÉCAPITULATIF!P6 -> 0
A6: 46266 | B6: EI | C6: EI527 | D6: 17H00 | E6: EI129754 | F6: 1 | G6: RUSH | I6: AUCUNE TRACE | K6: BSM ONLY | L6: APPEL DIRBY T1 A 16H41 MAIS INJOIGNABLE | M6: NON CHARGÉ | N6: 21 - Bag left at station origin / correctly labelled | P6: =COUNTIF($E$6:$E$1740,E6) -> 1 | Q6: =IF(AND(P6>1,COUNTIF($E$6:E6,E6)=1),MAX($Q$5:Q5)+1,"") | R6: =IF(Q6="","",IF(COUNTIFS($E$6:$E$1740,E6,$A$6:$A$1740,A6,$C$6:$C$1740,C6)<P6,"LÉGITIME",IF(COUNTIFS($E$6:$E$1740,E6,$A$6:$A$1740,A6,$C$6:$C$1740,C6,$M$6:$M$1740,M6)<P6,"STATUT DIFFÉRENT","VRAI DOUBLON")))
A7: 46266 | B7: EI | C7: EI527 | D7: 17H00 | E7: EI129755 | F7: 1 | G7: RUSH | I7: AUCUNE TRACE | K7: BSM ONLY | L7: APPEL DIRBY T1 A 16H41 MAIS INJOIGNABLE | M7: NON CHARGÉ | N7: 21 - Bag left at station origin / correctly labelled | P7: =COUNTIF($E$6:$E$1740,E7) -> 1 | Q7: =IF(AND(P7>1,COUNTIF($E$6:E7,E7)=1),MAX($Q$5:Q6)+1,"") | R7: =IF(Q7="","",IF(COUNTIFS($E$6:$E$1740,E7,$A$6:$A$1740,A7,$C$6:$C$1740,C7)<P7,"LÉGITIME",IF(COUNTIFS($E$6:$E$1740,E7,$A$6:$A$1740,A7,$C$6:$C$1740,C7,$M$6:$M$1740,M7)<P7,"STATUT DIFFÉRENT","VRAI DOUBLON")))
A8: 46266 | B8: EI | C8: EI527 | D8: 17H00 | E8: EI129756 | F8: 1 | G8: RUSH | I8: AUCUNE TRACE | K8: BSM ONLY | L8: APPEL DIRBY T1 A 16H41 MAIS INJOIGNABLE | M8: NON CHARGÉ | N8: 21 - Bag left at station origin / correctly labelled | P8: =COUNTIF($E$6:$E$1740,E8) -> 1 | Q8: =IF(AND(P8>1,COUNTIF($E$6:E8,E8)=1),MAX($Q$5:Q7)+1,"") | R8: =IF(Q8="","",IF(COUNTIFS($E$6:$E$1740,E8,$A$6:$A$1740,A8,$C$6:$C$1740,C8)<P8,"LÉGITIME",IF(COUNTIFS($E$6:$E$1740,E8,$A$6:$A$1740,A8,$C$6:$C$1740,C8,$M$6:$M$1740,M8)<P8,"STATUT DIFFÉRENT","VRAI DOUBLON")))
A9: 46266 | B9: EI | C9: EI527 | D9: 17H00 | E9: EI129757 | F9: 1 | G9: RUSH | I9: AUCUNE TRACE | K9: BSM ONLY | L9: APPEL DIRBY T1 A 16H41 MAIS INJOIGNABLE | M9: NON CHARGÉ | N9: 21 - Bag left at station origin / correctly labelled | P9: =COUNTIF($E$6:$E$1740,E9) -> 1 | Q9: =IF(AND(P9>1,COUNTIF($E$6:E9,E9)=1),MAX($Q$5:Q8)+1,"") | R9: =IF(Q9="","",IF(COUNTIFS($E$6:$E$1740,E9,$A$6:$A$1740,A9,$C$6:$C$1740,C9)<P9,"LÉGITIME",IF(COUNTIFS($E$6:$E$1740,E9,$A$6:$A$1740,A9,$C$6:$C$1740,C9,$M$6:$M$1740,M9)<P9,"STATUT DIFFÉRENT","VRAI DOUBLON")))
A10: 46267 | B10: EI | C10: EI521 | D10: 10H20 | E10: SQ658922 | F10: 1 | G10: NON NOTIFIE | I10: PAS DE TRACE | K10: PAS DE TRACE | L10: 09H41 : NEG DS TOUS SYSTEMES/J+1 MISCNX A SIN /RECU SUR LE SQ338/02SEP LOCALISE AN SLB 21H41 /DUBEI28745 FO EI523/03SEP | M10: NON CHARGÉ | N10: 56 - Online - own carrier - MCT not available | P10: =COUNTIF($E$6:$E$1740,E10) -> 1 | Q10: =IF(AND(P10>1,COUNTIF($E$6:E10,E10)=1),MAX($Q$5:Q9)+1,"") | R10: =IF(Q10="","",IF(COUNTIFS($E$6:$E$1740,E10,$A$6:$A$1740,A10,$C$6:$C$1740,C10)<P10,"LÉGITIME",IF(COUNTIFS($E$6:$E$1740,E10,$A$6:$A$1740,A10,$C$6:$C$1740,C10,$M$6:$M$1740,M10)<P10,"STATUT DIFFÉRENT","VRAI DOUBLON")))
A11: 46267 | B11: EI | C11: EI523 | D11: 11H15 | E11: EI129848 | F11: 1 | G11: LOCAL/RUSH | I11: T1 HORS FORMAT | L11: 10H37 : APPEL HORS FORMAT PUIS GALERIE T1 - BAG SERA DEPOSE SS BORD DES QU IL SERA TROUVE - PEUT ETRE CHARGE SS SCAN/J+1 DOSSIER TOUJOUR OUVERT | M11: NON CHARGÉ | N11: 21 - Bag left at station origin / correctly labelled | P11: =COUNTIF($E$6:$E$1740,E11) -> 1 | Q11: =IF(AND(P11>1,COUNTIF($E$6:E11,E11)=1),MAX($Q$5:Q10)+1,"") | R11: =IF(Q11="","",IF(COUNTIFS($E$6:$E$1740,E11,$A$6:$A$1740,A11,$C$6:$C$1740,C11)<P11,"LÉGITIME",IF(COUNTIFS($E$6:$E$1740,E11,$A$6:$A$1740,A11,$C$6:$C$1740,C11,$M$6:$M$1740,M11)<P11,"STATUT DIFFÉRENT","VRAI DOUBLON")))
A12: 46267 | B12: EI | C12: EI525 | D12: 13H15 | E12: EI215344 | F12: 1 | G12: LOCAL | I12: PAS DE LOC | K12: PAS DE LOC | L12: 7KG PROBABLEMENT PRIS EN PORTE | M12: CHARGÉ | P12: =COUNTIF($E$6:$E$1740,E12) -> 1 | Q12: =IF(AND(P12>1,COUNTIF($E$6:E12,E12)=1),MAX($Q$5:Q11)+1,"") | R12: =IF(Q12="","",IF(COUNTIFS($E$6:$E$1740,E12,$A$6:$A$1740,A12,$C$6:$C$1740,C12)<P12,"LÉGITIME",IF(COUNTIFS($E$6:$E$1740,E12,$A$6:$A$1740,A12,$C$6:$C$1740,C12,$M$6:$M$1740,M12)<P12,"STATUT DIFFÉRENT","VRAI DOUBLON")))
A13: 46267 | B13: EI | C13: EI525 | D13: 13H15 | E13: EI215655 | F13: 1 | G13: LOCAL | I13: PAS DE LOC | K13: CYNO OK 13H22 | L13: RETARD TRAITEMENT/J+1 DUBEI28761 EN ATTENTE DE FWD | M13: NON CHARGÉ | N13: 64 - Unserviceable equipment / belt / sortation system | P13: =COUNTIF($E$6:$E$1740,E13) -> 1 | Q13: =IF(AND(P13>1,COUNTIF($E$6:E13,E13)=1),MAX($Q$5:Q12)+1,"") | R13: =IF(Q13="","",IF(COUNTIFS($E$6:$E$1740,E13,$A$6:$A$1740,A13,$C$6:$C$1740,C13)<P13,"LÉGITIME",IF(COUNTIFS($E$6:$E$1740,E13,$A$6:$A$1740,A13,$C$6:$C$1740,C13,$M$6:$M$1740,M13)<P13,"STATUT DIFFÉRENT","VRAI DOUBLON")))
A14: 46267 | B14: EI | C14: EI529 | D14: 21H55 | E14: EI129974 | F14: 1 | G14: RUSH | I14: PAS DE TRACE | J14: BAG SOUTE S/SCAN | K14: BSM ONLY | L14: APPEL DIRBY T1 A 20H32 ET DEMANDE DE FAIRE LE NECESSAIRE/RUSH PAS EN GALERIE DOIT VERIF AVEC SES COLLEGUES EN SLB | M14: CHARGÉ | P14: =COUNTIF($E$6:$E$1740,E14) -> 1 | Q14: =IF(AND(P14>1,COUNTIF($E$6:E14,E14)=1),MAX($Q$5:Q13)+1,"") | R14: =IF(Q14="","",IF(COUNTIFS($E$6:$E$1740,E14,$A$6:$A$1740,A14,$C$6:$C$1740,C14)<P14,"LÉGITIME",IF(COUNTIFS($E$6:$E$1740,E14,$A$6:$A$1740,A14,$C$6:$C$1740,C14,$M$6:$M$1740,M14)<P14,"STATUT DIFFÉRENT","VRAI DOUBLON")))
A15: 46268 | B15: EI | C15: EI909 | D15: 11H10 | E15: EI217604 | F15: 1 | G15: LOCAL | I15: JETEE T1 09H06 | K15: CLASSE NON CORRECTE | L15: BAG CHARGE EN CONTENANT AKH67388EI/ J+1 SNNEI76763 EN ATTENTE DE FWD | M15: NON CHARGÉ | N15: 18 - Bag not authorized to load | P15: =COUNTIF($E$6:$E$1740,E15) -> 1 | Q15: =IF(AND(P15>1,COUNTIF($E$6:E15,E15)=1),MAX($Q$5:Q14)+1,"") | R15: =IF(Q15="","",IF(COUNTIFS($E$6:$E$1740,E15,$A$6:$A$1740,A15,$C$6:$C$1740,C15)<P15,"LÉGITIME",IF(COUNTIFS($E$6:$E$1740,E15,$A$6:$A$1740,A15,$C$6:$C$1740,C15,$M$6:$M$1740,M15)<P15,"STATUT DIFFÉRENT","VRAI DOUBLON")))
A16: 46268 | B16: EI | C16: EI909 | D16: 11H10 | E16: EI217607 | F16: 1 | G16: LOCAL | I16: T1 ARRIVEE 2 10H45 | L16: BAG DECHARGE DE CONTENANT AKH67388EI ET DEPOSE T1 ARRIVEE/ J+1 SNNEI76763 EN ATTENTE DE FWD | M16: NON CHARGÉ | N16: 18 - Bag not authorized to load | P16: =COUNTIF($E$6:$E$1740,E16) -> 1 | Q16: =IF(AND(P16>1,COUNTIF($E$6:E16,E16)=1),MAX($Q$5:Q15)+1,"") | R16: =IF(Q16="","",IF(COUNTIFS($E$6:$E$1740,E16,$A$6:$A$1740,A16,$C$6:$C$1740,C16)<P16,"LÉGITIME",IF(COUNTIFS($E$6:$E$1740,E16,$A$6:$A$1740,A16,$C$6:$C$1740,C16,$M$6:$M$1740,M16)<P16,"STATUT DIFFÉRENT","VRAI DOUBLON")))
A17: 46268 | B17: EI | C17: EI909 | D17: 11H10 | E17: MH871123 | F17: 1 | G17: MH021 | H17: 06H21 | I17: T1 ARRIVEE 2 10H45 | K17: ARRIVEE TARDIVE | L17: DECHARGE DE NAVETTE 08H22 SAT 1 / BAG ENVOYE SOUS BORD MAIS REFUSE /ENOIYE JETEE T1 10H44/RETOUR LL ET DEPOSE T1 ARRIVEE 10H44/ J+1 SNNEI76762 EN ATTENTE DE FWD | M17: NON CHARGÉ | N17: 18 - Bag not authorized to load | P17: =COUNTIF($E$6:$E$1740,E17) -> 1 | Q17: =IF(AND(P17>1,COUNTIF($E$6:E17,E17)=1),MAX($Q$5:Q16)+1,"") | R17: =IF(Q17="","",IF(COUNTIFS($E$6:$E$1740,E17,$A$6:$A$1740,A17,$C$6:$C$1740,C17)<P17,"LÉGITIME",IF(COUNTIFS($E$6:$E$1740,E17,$A$6:$A$1740,A17,$C$6:$C$1740,C17,$M$6:$M$1740,M17)<P17,"STATUT DIFFÉRENT","VRAI DOUBLON")))
A18: 46268 | B18: EI | C18: EI523 | D18: 11H15 | E18: EI218542 | F18: 1 | G18: LOCAL | I18: T1 EJECTION 10H34 | L18: EJECTION TARDIVE/ J+1 DUBEI28845 EN ATTENTE DE FWD | M18: NON CHARGÉ | N18: 64 - Unserviceable equipment / belt / sortation system | P18: =COUNTIF($E$6:$E$1740,E18) -> 1 | Q18: =IF(AND(P18>1,COUNTIF($E$6:E18,E18)=1),MAX($Q$5:Q17)+1,"") | R18: =IF(Q18="","",IF(COUNTIFS($E$6:$E$1740,E18,$A$6:$A$1740,A18,$C$6:$C$1740,C18)<P18,"LÉGITIME",IF(COUNTIFS($E$6:$E$1740,E18,$A$6:$A$1740,A18,$C$6:$C$1740,C18,$M$6:$M$1740,M18)<P18,"STATUT DIFFÉRENT","VRAI DOUBLON")))
A19: 46268 | B19: EI | C19: EI523 | D19: 11H15 | E19: EI218708 | F19: 1 | G19: LOCAL | I19: JETEE T1 11H41 | K19: EJECTION TARDIVE | L19: EJECTION TARDIVE BAG SCANNE SUR LE MAUVAIS VOL /J+1 DUBEI28845 EN ATTENTE DE FWD | M19: NON CHARGÉ | N19: 64 - Unserviceable equipment / belt / sortation system | P19: =COUNTIF($E$6:$E$1740,E19) -> 1 | Q19: =IF(AND(P19>1,COUNTIF($E$6:E19,E19)=1),MAX($Q$5:Q18)+1,"") | R19: =IF(Q19="","",IF(COUNTIFS($E$6:$E$1740,E19,$A$6:$A$1740,A19,$C$6:$C$1740,C19)<P19,"LÉGITIME",IF(COUNTIFS($E$6:$E$1740,E19,$A$6:$A$1740,A19,$C$6:$C$1740,C19,$M$6:$M$1740,M19)<P19,"STATUT DIFFÉRENT","VRAI DOUBLON")))
A20: 46268 | B20: EI | C20: EI523 | D20: 11H15 | E20: UA238710 | F20: 1 | G20: UA915 | H20: 07H49 | I20: SAT 1 /08H09 | K20: EJECTION TARDIVE | L20: EJETION JETEE T1 A 10H44/DEPOSE T1 ARRIVEE LL/ J+1 DUBEI28848 | M20: NON CHARGÉ | N20: 64 - Unserviceable equipment / belt / sortation system | P20: =COUNTIF($E$6:$E$1740,E20) -> 1 | Q20: =IF(AND(P20>1,COUNTIF($E$6:E20,E20)=1),MAX($Q$5:Q19)+1,"") | R20: =IF(Q20="","",IF(COUNTIFS($E$6:$E$1740,E20,$A$6:$A$1740,A20,$C$6:$C$1740,C20)<P20,"LÉGITIME",IF(COUNTIFS($E$6:$E$1740,E20,$A$6:$A$1740,A20,$C$6:$C$1740,C20,$M$6:$M$1740,M20)<P20,"STATUT DIFFÉRENT","VRAI DOUBLON")))
A21: 46268 | B21: EI | C21: EI523 | D21: 11H15 | E21: UA189600 | F21: 1 | G21: UA915 | H21: 07H49 | I21: JETEE T1 10H43 | K21: EJECTION TARDIVE | L21: EJETION JETEE T1 A 10H44/DEPOSE T1 ARRIVEE LL/ J+1 DUBEI28848 | M21: NON CHARGÉ | N21: 64 - Unserviceable equipment / belt / sortation system | P21: =COUNTIF($E$6:$E$1740,E21) -> 1 | Q21: =IF(AND(P21>1,COUNTIF($E$6:E21,E21)=1),MAX($Q$5:Q20)+1,"") | R21: =IF(Q21="","",IF(COUNTIFS($E$6:$E$1740,E21,$A$6:$A$1740,A21,$C$6:$C$1740,C21)<P21,"LÉGITIME",IF(COUNTIFS($E$6:$E$1740,E21,$A$6:$A$1740,A21,$C$6:$C$1740,C21,$M$6:$M$1740,M21)<P21,"STATUT DIFFÉRENT","VRAI DOUBLON")))
A22: 46268 | B22: EI | C22: EI523 | D22: 11H15 | E22: UA032310 | F22: 1 | G22: UA915 | H22: 07H49 | I22: SAT 1 /08H09 | K22: EJECTION TARDIVE | L22: EJETION JETEE T1 A 10H44/DEPOSE T1 ARRIVEE LL/ J+1 DUBEI28848 | M22: NON CHARGÉ | N22: 64 - Unserviceable equipment / belt / sortation system | P22: =COUNTIF($E$6:$E$1740,E22) -> 1 | Q22: =IF(AND(P22>1,COUNTIF($E$6:E22,E22)=1),MAX($Q$5:Q21)+1,"") | R22: =IF(Q22="","",IF(COUNTIFS($E$6:$E$1740,E22,$A$6:$A$1740,A22,$C$6:$C$1740,C22)<P22,"LÉGITIME",IF(COUNTIFS($E$6:$E$1740,E22,$A$6:$A$1740,A22,$C$6:$C$1740,C22,$M$6:$M$1740,M22)<P22,"STATUT DIFFÉRENT","VRAI DOUBLON")))
A23: 46268 | B23: EI | C23: EI523 | D23: 11H15 | E23: MH870031 | F23: 1 | G23: MH021 | H23: 06H21 | I23: JETEE T1 10GH44 | K23: EJECTION TARDIVE | L23: EJETION JETEE T1 A 10H44/DEPOSE T1 ARRIVEE LL/ J+1 DUBEI28855 | M23: NON CHARGÉ | N23: 64 - Unserviceable equipment / belt / sortation system | P23: =COUNTIF($E$6:$E$1740,E23) -> 1 | Q23: =IF(AND(P23>1,COUNTIF($E$6:E23,E23)=1),MAX($Q$5:Q22)+1,"") | R23: =IF(Q23="","",IF(COUNTIFS($E$6:$E$1740,E23,$A$6:$A$1740,A23,$C$6:$C$1740,C23)<P23,"LÉGITIME",IF(COUNTIFS($E$6:$E$1740,E23,$A$6:$A$1740,A23,$C$6:$C$1740,C23,$M$6:$M$1740,M23)<P23,"STATUT DIFFÉRENT","VRAI DOUBLON")))
A24: 46268 | B24: EI | C24: EI523 | D24: 11H15 | E24: MH869996 | F24: 1 | G24: MH021 | H24: 06H21 | I24: JETEE T1 10H44 | K24: EJECTION TARDIVE | L24: EJETION JETEE T1 A 10H44/DEPOSE T1 ARRIVEE LL/ J+1 DUBEI28855 | M24: NON CHARGÉ | N24: 64 - Unserviceable equipment / belt / sortation system | P24: =COUNTIF($E$6:$E$1740,E24) -> 1 | Q24: =IF(AND(P24>1,COUNTIF($E$6:E24,E24)=1),MAX($Q$5:Q23)+1,"") | R24: =IF(Q24="","",IF(COUNTIFS($E$6:$E$1740,E24,$A$6:$A$1740,A24,$C$6:$C$1740,C24)<P24,"LÉGITIME",IF(COUNTIFS($E$6:$E$1740,E24,$A$6:$A$1740,A24,$C$6:$C$1740,C24,$M$6:$M$1740,M24)<P24,"STATUT DIFFÉRENT","VRAI DOUBLON")))
A25: 46268 | B25: EI | C25: EI523 | D25: 11H15 | E25: MH869978 | F25: 1 | G25: MH021 | H25: 06H21 | I25: JETEE T1 10H44 | K25: EJECTION TARDIVE | L25: EJETION JETEE T1 A 10H44/DEPOSE T1 ARRIVEE LL/ J+1 DUBEI28855 | M25: NON CHARGÉ | N25: 64 - Unserviceable equipment / belt / sortation system | P25: =COUNTIF($E$6:$E$1740,E25) -> 1 | Q25: =IF(AND(P25>1,COUNTIF($E$6:E25,E25)=1),MAX($Q$5:Q24)+1,"") | R25: =IF(Q25="","",IF(COUNTIFS($E$6:$E$1740,E25,$A$6:$A$1740,A25,$C$6:$C$1740,C25)<P25,"LÉGITIME",IF(COUNTIFS($E$6:$E$1740,E25,$A$6:$A$1740,A25,$C$6:$C$1740,C25,$M$6:$M$1740,M25)<P25,"STATUT DIFFÉRENT","VRAI DOUBLON")))
A26: 46268 | B26: EI | C26: EI523 | D26: 11H15 | E26: MH869966 | F26: 1 | G26: MH021 | H26: 06H21 | I26: JETEE T1 10H44 | K26: EJECTION TARDIVE | L26: EJETION JETEE T1 A 10H44/DEPOSE T1 ARRIVEE LL/ J+1 DUBEI28855 | M26: NON CHARGÉ | N26: 64 - Unserviceable equipment / belt / sortation system | P26: =COUNTIF($E$6:$E$1740,E26) -> 1 | Q26: =IF(AND(P26>1,COUNTIF($E$6:E26,E26)=1),MAX($Q$5:Q25)+1,"") | R26: =IF(Q26="","",IF(COUNTIFS($E$6:$E$1740,E26,$A$6:$A$1740,A26,$C$6:$C$1740,C26)<P26,"LÉGITIME",IF(COUNTIFS($E$6:$E$1740,E26,$A$6:$A$1740,A26,$C$6:$C$1740,C26,$M$6:$M$1740,M26)<P26,"STATUT DIFFÉRENT","VRAI DOUBLON")))
A27: 46268 | B27: EI | C27: EI523 | D27: 11H15 | E27: MH872323 | F27: 1 | G27: MH021 | H27: 06H21 | I27: BSM ONLY | K27: PAS DE TRACE | L27: EJETION JETEE T1 A 10H44/DEPOSE T1 ARRIVEE LL/ J+1 DUBEI28855 | M27: NON CHARGÉ | N27: 64 - Unserviceable equipment / belt / sortation system | P27: =COUNTIF($E$6:$E$1740,E27) -> 1 | Q27: =IF(AND(P27>1,COUNTIF($E$6:E27,E27)=1),MAX($Q$5:Q26)+1,"") | R27: =IF(Q27="","",IF(COUNTIFS($E$6:$E$1740,E27,$A$6:$A$1740,A27,$C$6:$C$1740,C27)<P27,"LÉGITIME",IF(COUNTIFS($E$6:$E$1740,E27,$A$6:$A$1740,A27,$C$6:$C$1740,C27,$M$6:$M$1740,M27)<P27,"STATUT DIFFÉRENT","VRAI DOUBLON")))
A28: 46268 | B28: EI | C28: EI523 | D28: 11H15 | E28: EI218711 | F28: 1 | G28: LOCAL | I28: JETEE T1 11H42 | K28: EJECTION TARDIVE | L28: BAG SCANNE SUR UN AUTRE VOL EI525/ J+1 DUBEI28841 | M28: NON CHARGÉ | N28: 66- responsibility airport services | P28: =COUNTIF($E$6:$E$1740,E28) -> 1 | Q28: =IF(AND(P28>1,COUNTIF($E$6:E28,E28)=1),MAX($Q$5:Q27)+1,"") | R28: =IF(Q28="","",IF(COUNTIFS($E$6:$E$1740,E28,$A$6:$A$1740,A28,$C$6:$C$1740,C28)<P28,"LÉGITIME",IF(COUNTIFS($E$6:$E$1740,E28,$A$6:$A$1740,A28,$C$6:$C$1740,C28,$M$6:$M$1740,M28)<P28,"STATUT DIFFÉRENT","VRAI DOUBLON")))
A29: 46268 | B29: EI | C29: EI523 | D29: 11H15 | E29: AF155186 | F29: 1 | G29: AF453 | H29: 07H05 | I29: JETEE T1 11H55 | K29: EJECTION TARDIVE | L29: BAG SCANNE SUR UN AUTRE VOL EI525/ J+1 DUBEI28857 | M29: NON CHARGÉ | N29: 66- responsibility airport services | P29: =COUNTIF($E$6:$E$1740,E29) -> 1 | Q29: =IF(AND(P29>1,COUNTIF($E$6:E29,E29)=1),MAX($Q$5:Q28)+1,"") | R29: =IF(Q29="","",IF(COUNTIFS($E$6:$E$1740,E29,$A$6:$A$1740,A29,$C$6:$C$1740,C29)<P29,"LÉGITIME",IF(COUNTIFS($E$6:$E$1740,E29,$A$6:$A$1740,A29,$C$6:$C$1740,C29,$M$6:$M$1740,M29)<P29,"STATUT DIFFÉRENT","VRAI DOUBLON")))
A30: 46268 | B30: EI | C30: EI523 | D30: 11H15 | E30: AC574766 | F30: 1 | G30: UA915 | H30: 07H49 | I30: BSM ONLY | K30: PAS DE TRACE | L30: VU EN REQUETEUR/PAS DE TRACE A CDG/ MICNX IAD J+1 DUBEI28847 FO UA915/02SEP/EI521/03SEP NON RECU | M30: NON CHARGÉ | N30: 56 - Online - own carrier - MCT not available | P30: =COUNTIF($E$6:$E$1740,E30) -> 1 | Q30: =IF(AND(P30>1,COUNTIF($E$6:E30,E30)=1),MAX($Q$5:Q29)+1,"") | R30: =IF(Q30="","",IF(COUNTIFS($E$6:$E$1740,E30,$A$6:$A$1740,A30,$C$6:$C$1740,C30)<P30,"LÉGITIME",IF(COUNTIFS($E$6:$E$1740,E30,$A$6:$A$1740,A30,$C$6:$C$1740,C30,$M$6:$M$1740,M30)<P30,"STATUT DIFFÉRENT","VRAI DOUBLON")))
A31: 46268 | B31: EI | C31: EI523 | D31: 11H15 | E31: MH872673 | F31: 1 | G31: MH021 | H31: 06H21 | I31: BSM ONLY | K31: PAS DE TRACE | L31: VU EN REQUETEUR/PAS DE TRACE A CDG/ J+1 DUBEI28842 | M31: NON CHARGÉ | N31: 64 - Unserviceable equipment / belt / sortation system | P31: =COUNTIF($E$6:$E$1740,E31) -> 1 | Q31: =IF(AND(P31>1,COUNTIF($E$6:E31,E31)=1),MAX($Q$5:Q30)+1,"") | R31: =IF(Q31="","",IF(COUNTIFS($E$6:$E$1740,E31,$A$6:$A$1740,A31,$C$6:$C$1740,C31)<P31,"LÉGITIME",IF(COUNTIFS($E$6:$E$1740,E31,$A$6:$A$1740,A31,$C$6:$C$1740,C31,$M$6:$M$1740,M31)<P31,"STATUT DIFFÉRENT","VRAI DOUBLON")))
A32: 46268 | B32: EI | C32: EI523 | D32: 11H15 | E32: UA015580 | F32: 1 | G32: UA915 | H32: 07H49 | I32: BSM ONLY | J32: HBAG | K32: PAS DE TRACE | L32: VU EN REQUETEUR/PAS DE TRACE A CDG/ J+1 PAS DE DOSSIER OUVERT AVEC CE TAG | M32: CHARGÉ | P32: =COUNTIF($E$6:$E$1740,E32) -> 1 | Q32: =IF(AND(P32>1,COUNTIF($E$6:E32,E32)=1),MAX($Q$5:Q31)+1,"") | R32: =IF(Q32="","",IF(COUNTIFS($E$6:$E$1740,E32,$A$6:$A$1740,A32,$C$6:$C$1740,C32)<P32,"LÉGITIME",IF(COUNTIFS($E$6:$E$1740,E32,$A$6:$A$1740,A32,$C$6:$C$1740,C32,$M$6:$M$1740,M32)<P32,"STATUT DIFFÉRENT","VRAI DOUBLON")))
A33: 46268 | B33: EI | C33: EI523 | D33: 11H15 | E33: UA879071 | F33: 1 | G33: UA915 | H33: 07H49 | I33: BSM ONLY | K33: PAS DE TRACE | L33: VU EN REQUETEUR/PAS DE TRACE A CDG MISCNX AT IAD / J+1 DUBEI28843 FO UA310/05SEP | M33: NON CHARGÉ | N33: 56 - Online - own carrier - MCT not available | P33: =COUNTIF($E$6:$E$1740,E33) -> 1 | Q33: =IF(AND(P33>1,COUNTIF($E$6:E33,E33)=1),MAX($Q$5:Q32)+1,"") | R33: =IF(Q33="","",IF(COUNTIFS($E$6:$E$1740,E33,$A$6:$A$1740,A33,$C$6:$C$1740,C33)<P33,"LÉGITIME",IF(COUNTIFS($E$6:$E$1740,E33,$A$6:$A$1740,A33,$C$6:$C$1740,C33,$M$6:$M$1740,M33)<P33,"STATUT DIFFÉRENT","VRAI DOUBLON")))
A34: 46268 | B34: EI | C34: EI525 | D34: 13H15 | E34: EI218815 | F34: 1 | G34: LOCAL | I34: BSM ONLY | J34: STRL | L34: STROLLER | M34: CHARGÉ | P34: =COUNTIF($E$6:$E$1740,E34) -> 1 | Q34: =IF(AND(P34>1,COUNTIF($E$6:E34,E34)=1),MAX($Q$5:Q33)+1,"") | R34: =IF(Q34="","",IF(COUNTIFS($E$6:$E$1740,E34,$A$6:$A$1740,A34,$C$6:$C$1740,C34)<P34,"LÉGITIME",IF(COUNTIFS($E$6:$E$1740,E34,$A$6:$A$1740,A34,$C$6:$C$1740,C34,$M$6:$M$1740,M34)<P34,"STATUT DIFFÉRENT","VRAI DOUBLON")))
A35: 46268 | B35: EI | C35: EI523 | D35: 16H30 | E35: EI219420 | F35: 1 | G35: LOCAL | I35: BSM ONLY | J35: WCH | K35: PAS DE TRACE | L35: WCHR/APPEL LEAD EI A 16H30/APPELE LE COORDO A SON TOUR/ASSURE QUE LA CHAISE A ÉTÉ CHARGEE MAIS PAS SCANNE/SCANNE MANUELLEMENT APRES LE DEP | M35: SAUVÉ | P35: =COUNTIF($E$6:$E$1740,E35) -> 1 | Q35: =IF(AND(P35>1,COUNTIF($E$6:E35,E35)=1),MAX($Q$5:Q34)+1,"") | R35: =IF(Q35="","",IF(COUNTIFS($E$6:$E$1740,E35,$A$6:$A$1740,A35,$C$6:$C$1740,C35)<P35,"LÉGITIME",IF(COUNTIFS($E$6:$E$1740,E35,$A$6:$A$1740,A35,$C$6:$C$1740,C35,$M$6:$M$1740,M35)<P35,"STATUT DIFFÉRENT","VRAI DOUBLON")))
A36: 46268 | B36: EI | C36: EI523 | D36: 21H55 | E36: EI130152 | F36: 1 | G36: RUSH | I36: AUCUNE TRACE | K36: BSM ONLY 16H27 | L36: APPEL DIRBY T1 A 21H07/DIT QUE LE RUSH A BIEN ÉTÉ ENVOYE MALGRE LE MANQUE DE TRACE/APPEL SUP GALERIE T1 /RUSH EN GAL MAIS PAS SCANNE | M36: SAUVÉ | P36: =COUNTIF($E$6:$E$1740,E36) -> 1 | Q36: =IF(AND(P36>1,COUNTIF($E$6:E36,E36)=1),MAX($Q$5:Q35)+1,"") | R36: =IF(Q36="","",IF(COUNTIFS($E$6:$E$1740,E36,$A$6:$A$1740,A36,$C$6:$C$1740,C36)<P36,"LÉGITIME",IF(COUNTIFS($E$6:$E$1740,E36,$A$6:$A$1740,A36,$C$6:$C$1740,C36,$M$6:$M$1740,M36)<P36,"STATUT DIFFÉRENT","VRAI DOUBLON")))
A37: 46268 | B37: EI | C37: EI523 | D37: 21H55 | E37: EI130151 | F37: 1 | G37: RUSH | I37: T1 CYNO MJ90 21H09 | K37: PAS DE MVT | L37: APPEL GALERIE T1 A 21H12 ET SIGNALE POUR LE RECUPERER | M37: SAUVÉ | P37: =COUNTIF($E$6:$E$1740,E37) -> 1 | Q37: =IF(AND(P37>1,COUNTIF($E$6:E37,E37)=1),MAX($Q$5:Q36)+1,"") | R37: =IF(Q37="","",IF(COUNTIFS($E$6:$E$1740,E37,$A$6:$A$1740,A37,$C$6:$C$1740,C37)<P37,"LÉGITIME",IF(COUNTIFS($E$6:$E$1740,E37,$A$6:$A$1740,A37,$C$6:$C$1740,C37,$M$6:$M$1740,M37)<P37,"STATUT DIFFÉRENT","VRAI DOUBLON")))
A38: 46269 | B38: EI | C38: EI521 | D38: 10H20 | E38: AF256896 | F38: 1 | G38: AF4199 | H38: 08H25 | I38: WJ43 09H53 | K38: SHORT CONNEX | L38: APPEL GALERIE T1 POUR ENVOIE SOUS BORD | M38: SAUVÉ | P38: =COUNTIF($E$6:$E$1740,E38) -> 1 | Q38: =IF(AND(P38>1,COUNTIF($E$6:E38,E38)=1),MAX($Q$5:Q37)+1,"") | R38: =IF(Q38="","",IF(COUNTIFS($E$6:$E$1740,E38,$A$6:$A$1740,A38,$C$6:$C$1740,C38)<P38,"LÉGITIME",IF(COUNTIFS($E$6:$E$1740,E38,$A$6:$A$1740,A38,$C$6:$C$1740,C38,$M$6:$M$1740,M38)<P38,"STATUT DIFFÉRENT","VRAI DOUBLON")))
A39: 46269 | B39: EI | C39: EI521 | D39: 10H20 | E39: BR703261 | F39: 1 | H39: 08H25 | I39: REBUT T1 | L39: APPEL GALERIE T1 POUR ENVOIE SOUS BORD A 09H40 PUIS LOCALISE AU REBUT T1 A 09H53 - AHLDUBEI28991 PAS DE RUSH PREVU A J+1 | M39: NON CHARGÉ | N39: 66- responsibility airport services | P39: =COUNTIF($E$6:$E$1740,E39) -> 1 | Q39: =IF(AND(P39>1,COUNTIF($E$6:E39,E39)=1),MAX($Q$5:Q38)+1,"") | R39: =IF(Q39="","",IF(COUNTIFS($E$6:$E$1740,E39,$A$6:$A$1740,A39,$C$6:$C$1740,C39)<P39,"LÉGITIME",IF(COUNTIFS($E$6:$E$1740,E39,$A$6:$A$1740,A39,$C$6:$C$1740,C39,$M$6:$M$1740,M39)<P39,"STATUT DIFFÉRENT","VRAI DOUBLON")))
A40: 46269 | B40: EI | C40: EI521 | D40: 10H20 | E40: AF245898 | F40: 1 | G40: AF4199 | H40: 08H25 | I40: DECHARGE AU SAT1 A 10H29 | K40: SHORT CONNEX | L40: ARRIVE AU SAT T1 A 10H29 TROP TARD POUR CHARGEMENT - AHLDUBEI28990 PAS DE RUSH PREVU A J+1 | M40: NON CHARGÉ | N40: 52 - Interline MCT not available ( MCT initialement non respecté) | P40: =COUNTIF($E$6:$E$1740,E40) -> 1 | Q40: =IF(AND(P40>1,COUNTIF($E$6:E40,E40)=1),MAX($Q$5:Q39)+1,"") | R40: =IF(Q40="","",IF(COUNTIFS($E$6:$E$1740,E40,$A$6:$A$1740,A40,$C$6:$C$1740,C40)<P40,"LÉGITIME",IF(COUNTIFS($E$6:$E$1740,E40,$A$6:$A$1740,A40,$C$6:$C$1740,C40,$M$6:$M$1740,M40)<P40,"STATUT DIFFÉRENT","VRAI DOUBLON")))
...
