Workbook

Sheet RÉCAPITULATIF
A1: ALYZIA | RÉCAPITULATIF
A3: COMPTE RENDU DE SUPERVISION • SEPTEMBRE 2026 • TOUTES COMPAGNIES
A5: DOSSIERS | D5: BAGAGES ATTENDUS | G5: SAUVÉS | J5: CHARGÉS | M5: NON CHARGÉS | P5: ANNULÉS | S5: TAGS EN DOUBLE
A6: =SUM(B14:B27) -> 1735 | D6: =SUM(D14:D27) -> 106188 | G6: =SUM(E14:E27) -> 773 | J6: =SUM(F14:F27) -> 369 | M6: =SUM(G14:G27) -> 593 | P6: =SUM(H14:H27) -> 0 | S6: =MAX(BASE!$Q$6:$Q$1740) -> 26
A8: TAUX DE TRAITEMENT | D8: DOSSIERS TRAITÉS | G8: % SAUVÉS | J8: % CHARGÉS | M8: % NON CHARGÉS | P8: % ANNULÉS | S8: LIGNES CONCERNÉES
A9: =IFERROR((G6+J6+M6+P6)/A6,0) -> 1 | D9: =SUM(G6,J6,M6,P6) -> 1735 | G9: =G6/$A$6 -> 0.44553314 | J9: =J6/$A$6 -> 0.21268012 | M9: =M6/$A$6 -> 0.34178674 | P9: =P6/$A$6 -> 0 | S9: =COUNTIF(BASE!$P$6:$P$1740,">1") -> 52
A12: RÉPARTITION PAR COMPAGNIE | AA12: COMPAGNIE | AB12: SAUVÉS | AC12: CHARGÉS | AD12: NON CHARGÉS | AE12: ANNULÉS
A13: CIE | B13: DOSSIERS | C13: BAG. TRAITÉS | D13: ATTENDUS | E13: SAUVÉS | F13: CHARGÉS | G13: NON CHARGÉS | H13: ANNULÉS | I13: TAUX SAUVÉS | AA13: AI | AB13: =SUMIF($A$14:$A$27,AA13,$E$14:$E$27) -> 93 | AC13: =SUMIF($A$14:$A$27,AA13,$F$14:$F$27) -> 13 | AD13: =SUMIF($A$14:$A$27,AA13,$G$14:$G$27) -> 60 | AE13: =SUMIF($A$14:$A$27,AA13,$H$14:$H$27) -> 0
A14: SK | B14: =COUNTIF(BASE!$B$6:$B$1740,A14) -> 133 | C14: =SUMIF(BASE!$B$6:$B$1740,A14,BASE!$F$6:$F$1740) -> 133 | D14: 4758 | E14: =COUNTIFS(BASE!$B$6:$B$1740,A14,BASE!$M$6:$M$1740,"SAUVÉ") -> 62 | F14: =COUNTIFS(BASE!$B$6:$B$1740,A14,BASE!$M$6:$M$1740,"CHARGÉ") -> 13 | G14: =COUNTIFS(BASE!$B$6:$B$1740,A14,BASE!$M$6:$M$1740,"NON CHARGÉ") -> 58 | H14: =COUNTIFS(BASE!$B$6:$B$1740,A14,BASE!$M$6:$M$1740,"ANNULÉ") -> 0 | I14: =IFERROR(E14/B14,0) -> 0.46616541 | AA14: AT | AB14: =SUMIF($A$14:$A$27,AA14,$E$14:$E$27) -> 94 | AC14: =SUMIF($A$14:$A$27,AA14,$F$14:$F$27) -> 45 | AD14: =SUMIF($A$14:$A$27,AA14,$G$14:$G$27) -> 45 | AE14: =SUMIF($A$14:$A$27,AA14,$H$14:$H$27) -> 0
A15: AI | B15: =COUNTIF(BASE!$B$6:$B$1740,A15) -> 166 | C15: =SUMIF(BASE!$B$6:$B$1740,A15,BASE!$F$6:$F$1740) -> 166 | D15: =SUM('SYNTHÈSE PAR DATE'!J6:J35) -> 9011 | E15: =COUNTIFS(BASE!$B$6:$B$1740,A15,BASE!$M$6:$M$1740,"SAUVÉ") -> 93 | F15: =COUNTIFS(BASE!$B$6:$B$1740,A15,BASE!$M$6:$M$1740,"CHARGÉ") -> 13 | G15: =COUNTIFS(BASE!$B$6:$B$1740,A15,BASE!$M$6:$M$1740,"NON CHARGÉ") -> 60 | H15: =COUNTIFS(BASE!$B$6:$B$1740,A15,BASE!$M$6:$M$1740,"ANNULÉ") -> 0 | I15: =IFERROR(E15/B15,0) -> 0.56024096 | AA15: AV | AB15: =SUMIF($A$14:$A$27,AA15,$E$14:$E$27) -> 49 | AC15: =SUMIF($A$14:$A$27,AA15,$F$14:$F$27) -> 16 | AD15: =SUMIF($A$14:$A$27,AA15,$G$14:$G$27) -> 36 | AE15: =SUMIF($A$14:$A$27,AA15,$H$14:$H$27) -> 0
A16: EI | B16: =COUNTIF(BASE!$B$6:$B$1740,A16) -> 302 | C16: =SUMIF(BASE!$B$6:$B$1740,A16,BASE!$F$6:$F$1740) -> 302 | D16: =SUM('SYNTHÈSE PAR DATE'!K6:K35) -> 17510 | E16: =COUNTIFS(BASE!$B$6:$B$1740,A16,BASE!$M$6:$M$1740,"SAUVÉ") -> 44 | F16: =COUNTIFS(BASE!$B$6:$B$1740,A16,BASE!$M$6:$M$1740,"CHARGÉ") -> 82 | G16: =COUNTIFS(BASE!$B$6:$B$1740,A16,BASE!$M$6:$M$1740,"NON CHARGÉ") -> 176 | H16: =COUNTIFS(BASE!$B$6:$B$1740,A16,BASE!$M$6:$M$1740,"ANNULÉ") -> 0 | I16: =IFERROR(E16/B16,0) -> 0.14569536 | AA16: DE | AB16: =SUMIF($A$14:$A$27,AA16,$E$14:$E$27) -> 53 | AC16: =SUMIF($A$14:$A$27,AA16,$F$14:$F$27) -> 49 | AD16: =SUMIF($A$14:$A$27,AA16,$G$14:$G$27) -> 19 | AE16: =SUMIF($A$14:$A$27,AA16,$H$14:$H$27) -> 0
A17: LA | B17: =COUNTIF(BASE!$B$6:$B$1740,A17) -> 85 | C17: =SUMIF(BASE!$B$6:$B$1740,A17,BASE!$F$6:$F$1740) -> 85 | D17: =SUM('SYNTHÈSE PAR DATE'!L6:L35) -> 7669 | E17: =COUNTIFS(BASE!$B$6:$B$1740,A17,BASE!$M$6:$M$1740,"SAUVÉ") -> 17 | F17: =COUNTIFS(BASE!$B$6:$B$1740,A17,BASE!$M$6:$M$1740,"CHARGÉ") -> 39 | G17: =COUNTIFS(BASE!$B$6:$B$1740,A17,BASE!$M$6:$M$1740,"NON CHARGÉ") -> 29 | H17: =COUNTIFS(BASE!$B$6:$B$1740,A17,BASE!$M$6:$M$1740,"ANNULÉ") -> 0 | I17: =IFERROR(E17/B17,0) -> 0.2 | AA17: EI | AB17: =SUMIF($A$14:$A$27,AA17,$E$14:$E$27) -> 44 | AC17: =SUMIF($A$14:$A$27,AA17,$F$14:$F$27) -> 82 | AD17: =SUMIF($A$14:$A$27,AA17,$G$14:$G$27) -> 176 | AE17: =SUMIF($A$14:$A$27,AA17,$H$14:$H$27) -> 0
A18: HF | B18: =COUNTIF(BASE!$B$6:$B$1740,A18) -> 30 | C18: =SUMIF(BASE!$B$6:$B$1740,A18,BASE!$F$6:$F$1740) -> 30 | D18: =SUM('SYNTHÈSE PAR DATE'!M6:M35) -> 13252 | E18: =COUNTIFS(BASE!$B$6:$B$1740,A18,BASE!$M$6:$M$1740,"SAUVÉ") -> 8 | F18: =COUNTIFS(BASE!$B$6:$B$1740,A18,BASE!$M$6:$M$1740,"CHARGÉ") -> 16 | G18: =COUNTIFS(BASE!$B$6:$B$1740,A18,BASE!$M$6:$M$1740,"NON CHARGÉ") -> 6 | H18: =COUNTIFS(BASE!$B$6:$B$1740,A18,BASE!$M$6:$M$1740,"ANNULÉ") -> 0 | I18: =IFERROR(E18/B18,0) -> 0.26666667 | AA18: FI | AB18: =SUMIF($A$14:$A$27,AA18,$E$14:$E$27) -> 88 | AC18: =SUMIF($A$14:$A$27,AA18,$F$14:$F$27) -> 25 | AD18: =SUMIF($A$14:$A$27,AA18,$G$14:$G$27) -> 61 | AE18: =SUMIF($A$14:$A$27,AA18,$H$14:$H$27) -> 0
A19: SB | B19: =COUNTIF(BASE!$B$6:$B$1740,A19) -> 55 | C19: =SUMIF(BASE!$B$6:$B$1740,A19,BASE!$F$6:$F$1740) -> 55 | D19: =SUM('SYNTHÈSE PAR DATE'!N6:N35) -> 3602 | E19: =COUNTIFS(BASE!$B$6:$B$1740,A19,BASE!$M$6:$M$1740,"SAUVÉ") -> 38 | F19: =COUNTIFS(BASE!$B$6:$B$1740,A19,BASE!$M$6:$M$1740,"CHARGÉ") -> 7 | G19: =COUNTIFS(BASE!$B$6:$B$1740,A19,BASE!$M$6:$M$1740,"NON CHARGÉ") -> 10 | H19: =COUNTIFS(BASE!$B$6:$B$1740,A19,BASE!$M$6:$M$1740,"ANNULÉ") -> 0 | I19: =IFERROR(E19/B19,0) -> 0.69090909 | AA19: HF | AB19: =SUMIF($A$14:$A$27,AA19,$E$14:$E$27) -> 8 | AC19: =SUMIF($A$14:$A$27,AA19,$F$14:$F$27) -> 16 | AD19: =SUMIF($A$14:$A$27,AA19,$G$14:$G$27) -> 6 | AE19: =SUMIF($A$14:$A$27,AA19,$H$14:$H$27) -> 0
A20: DE | B20: =COUNTIF(BASE!$B$6:$B$1740,A20) -> 121 | C20: =SUMIF(BASE!$B$6:$B$1740,A20,BASE!$F$6:$F$1740) -> 121 | D20: =SUM('SYNTHÈSE PAR DATE'!O6:O35) -> 5215 | E20: =COUNTIFS(BASE!$B$6:$B$1740,A20,BASE!$M$6:$M$1740,"SAUVÉ") -> 53 | F20: =COUNTIFS(BASE!$B$6:$B$1740,A20,BASE!$M$6:$M$1740,"CHARGÉ") -> 49 | G20: =COUNTIFS(BASE!$B$6:$B$1740,A20,BASE!$M$6:$M$1740,"NON CHARGÉ") -> 19 | H20: =COUNTIFS(BASE!$B$6:$B$1740,A20,BASE!$M$6:$M$1740,"ANNULÉ") -> 0 | I20: =IFERROR(E20/B20,0) -> 0.43801653 | AA20: JU | AB20: =SUMIF($A$14:$A$27,AA20,$E$14:$E$27) -> 149 | AC20: =SUMIF($A$14:$A$27,AA20,$F$14:$F$27) -> 16 | AD20: =SUMIF($A$14:$A$27,AA20,$G$14:$G$27) -> 32 | AE20: =SUMIF($A$14:$A$27,AA20,$H$14:$H$27) -> 0
A21: MH | B21: =COUNTIF(BASE!$B$6:$B$1740,A21) -> 40 | C21: =SUMIF(BASE!$B$6:$B$1740,A21,BASE!$F$6:$F$1740) -> 40 | D21: =SUM('SYNTHÈSE PAR DATE'!P6:P35) -> 6770 | E21: =COUNTIFS(BASE!$B$6:$B$1740,A21,BASE!$M$6:$M$1740,"SAUVÉ") -> 12 | F21: =COUNTIFS(BASE!$B$6:$B$1740,A21,BASE!$M$6:$M$1740,"CHARGÉ") -> 4 | G21: =COUNTIFS(BASE!$B$6:$B$1740,A21,BASE!$M$6:$M$1740,"NON CHARGÉ") -> 24 | H21: =COUNTIFS(BASE!$B$6:$B$1740,A21,BASE!$M$6:$M$1740,"ANNULÉ") -> 0 | I21: =IFERROR(E21/B21,0) -> 0.3 | AA21: LA | AB21: =SUMIF($A$14:$A$27,AA21,$E$14:$E$27) -> 17 | AC21: =SUMIF($A$14:$A$27,AA21,$F$14:$F$27) -> 39 | AD21: =SUMIF($A$14:$A$27,AA21,$G$14:$G$27) -> 29 | AE21: =SUMIF($A$14:$A$27,AA21,$H$14:$H$27) -> 0
A22: RJ | B22: =COUNTIF(BASE!$B$6:$B$1740,A22) -> 45 | C22: =SUMIF(BASE!$B$6:$B$1740,A22,BASE!$F$6:$F$1740) -> 45 | D22: =SUM('SYNTHÈSE PAR DATE'!Q6:Q35) -> 4421 | E22: =COUNTIFS(BASE!$B$6:$B$1740,A22,BASE!$M$6:$M$1740,"SAUVÉ") -> 19 | F22: =COUNTIFS(BASE!$B$6:$B$1740,A22,BASE!$M$6:$M$1740,"CHARGÉ") -> 12 | G22: =COUNTIFS(BASE!$B$6:$B$1740,A22,BASE!$M$6:$M$1740,"NON CHARGÉ") -> 14 | H22: =COUNTIFS(BASE!$B$6:$B$1740,A22,BASE!$M$6:$M$1740,"ANNULÉ") -> 0 | I22: =IFERROR(E22/B22,0) -> 0.42222222 | AA22: LO | AB22: =SUMIF($A$14:$A$27,AA22,$E$14:$E$27) -> 47 | AC22: =SUMIF($A$14:$A$27,AA22,$F$14:$F$27) -> 32 | AD22: =SUMIF($A$14:$A$27,AA22,$G$14:$G$27) -> 23 | AE22: =SUMIF($A$14:$A$27,AA22,$H$14:$H$27) -> 0
A23: AV | B23: =COUNTIF(BASE!$B$6:$B$1740,A23) -> 101 | C23: =SUMIF(BASE!$B$6:$B$1740,A23,BASE!$F$6:$F$1740) -> 101 | D23: =SUM('SYNTHÈSE PAR DATE'!R6:R35) -> 5214 | E23: =COUNTIFS(BASE!$B$6:$B$1740,A23,BASE!$M$6:$M$1740,"SAUVÉ") -> 49 | F23: =COUNTIFS(BASE!$B$6:$B$1740,A23,BASE!$M$6:$M$1740,"CHARGÉ") -> 16 | G23: =COUNTIFS(BASE!$B$6:$B$1740,A23,BASE!$M$6:$M$1740,"NON CHARGÉ") -> 36 | H23: =COUNTIFS(BASE!$B$6:$B$1740,A23,BASE!$M$6:$M$1740,"ANNULÉ") -> 0 | I23: =IFERROR(E23/B23,0) -> 0.48514851 | AA23: MH | AB23: =SUMIF($A$14:$A$27,AA23,$E$14:$E$27) -> 12 | AC23: =SUMIF($A$14:$A$27,AA23,$F$14:$F$27) -> 4 | AD23: =SUMIF($A$14:$A$27,AA23,$G$14:$G$27) -> 24 | AE23: =SUMIF($A$14:$A$27,AA23,$H$14:$H$27) -> 0
A24: FI | B24: =COUNTIF(BASE!$B$6:$B$1740,A24) -> 174 | C24: =SUMIF(BASE!$B$6:$B$1740,A24,BASE!$F$6:$F$1740) -> 174 | D24: =SUM('SYNTHÈSE PAR DATE'!S6:S35) -> 9141 | E24: =COUNTIFS(BASE!$B$6:$B$1740,A24,BASE!$M$6:$M$1740,"SAUVÉ") -> 88 | F24: =COUNTIFS(BASE!$B$6:$B$1740,A24,BASE!$M$6:$M$1740,"CHARGÉ") -> 25 | G24: =COUNTIFS(BASE!$B$6:$B$1740,A24,BASE!$M$6:$M$1740,"NON CHARGÉ") -> 61 | H24: =COUNTIFS(BASE!$B$6:$B$1740,A24,BASE!$M$6:$M$1740,"ANNULÉ") -> 0 | I24: =IFERROR(E24/B24,0) -> 0.50574713 | AA24: RJ | AB24: =SUMIF($A$14:$A$27,AA24,$E$14:$E$27) -> 19 | AC24: =SUMIF($A$14:$A$27,AA24,$F$14:$F$27) -> 12 | AD24: =SUMIF($A$14:$A$27,AA24,$G$14:$G$27) -> 14 | AE24: =SUMIF($A$14:$A$27,AA24,$H$14:$H$27) -> 0
A25: AT | B25: =COUNTIF(BASE!$B$6:$B$1740,A25) -> 184 | C25: =SUMIF(BASE!$B$6:$B$1740,A25,BASE!$F$6:$F$1740) -> 184 | D25: =SUM('SYNTHÈSE PAR DATE'!T6:T35) -> 10427 | E25: =COUNTIFS(BASE!$B$6:$B$1740,A25,BASE!$M$6:$M$1740,"SAUVÉ") -> 94 | F25: =COUNTIFS(BASE!$B$6:$B$1740,A25,BASE!$M$6:$M$1740,"CHARGÉ") -> 45 | G25: =COUNTIFS(BASE!$B$6:$B$1740,A25,BASE!$M$6:$M$1740,"NON CHARGÉ") -> 45 | H25: =COUNTIFS(BASE!$B$6:$B$1740,A25,BASE!$M$6:$M$1740,"ANNULÉ") -> 0 | I25: =IFERROR(E25/B25,0) -> 0.51086957 | AA25: SB | AB25: =SUMIF($A$14:$A$27,AA25,$E$14:$E$27) -> 38 | AC25: =SUMIF($A$14:$A$27,AA25,$F$14:$F$27) -> 7 | AD25: =SUMIF($A$14:$A$27,AA25,$G$14:$G$27) -> 10 | AE25: =SUMIF($A$14:$A$27,AA25,$H$14:$H$27) -> 0
A26: JU | B26: =COUNTIF(BASE!$B$6:$B$1740,A26) -> 197 | C26: =SUMIF(BASE!$B$6:$B$1740,A26,BASE!$F$6:$F$1740) -> 197 | D26: =SUM('SYNTHÈSE PAR DATE'!U6:U35) -> 4332 | E26: =COUNTIFS(BASE!$B$6:$B$1740,A26,BASE!$M$6:$M$1740,"SAUVÉ") -> 149 | F26: =COUNTIFS(BASE!$B$6:$B$1740,A26,BASE!$M$6:$M$1740,"CHARGÉ") -> 16 | G26: =COUNTIFS(BASE!$B$6:$B$1740,A26,BASE!$M$6:$M$1740,"NON CHARGÉ") -> 32 | H26: =COUNTIFS(BASE!$B$6:$B$1740,A26,BASE!$M$6:$M$1740,"ANNULÉ") -> 0 | I26: =IFERROR(E26/B26,0) -> 0.75634518 | AA26: SK | AB26: =SUMIF($A$14:$A$27,AA26,$E$14:$E$27) -> 62 | AC26: =SUMIF($A$14:$A$27,AA26,$F$14:$F$27) -> 13 | AD26: =SUMIF($A$14:$A$27,AA26,$G$14:$G$27) -> 58 | AE26: =SUMIF($A$14:$A$27,AA26,$H$14:$H$27) -> 0
A27: LO | B27: =COUNTIF(BASE!$B$6:$B$1740,A27) -> 102 | C27: =SUMIF(BASE!$B$6:$B$1740,A27,BASE!$F$6:$F$1740) -> 102 | D27: =SUM('SYNTHÈSE PAR DATE'!V6:V35) -> 4866 | E27: =COUNTIFS(BASE!$B$6:$B$1740,A27,BASE!$M$6:$M$1740,"SAUVÉ") -> 47 | F27: =COUNTIFS(BASE!$B$6:$B$1740,A27,BASE!$M$6:$M$1740,"CHARGÉ") -> 32 | G27: =COUNTIFS(BASE!$B$6:$B$1740,A27,BASE!$M$6:$M$1740,"NON CHARGÉ") -> 23 | H27: =COUNTIFS(BASE!$B$6:$B$1740,A27,BASE!$M$6:$M$1740,"ANNULÉ") -> 0 | I27: =IFERROR(E27/B27,0) -> 0.46078431
A28: TOTAL | B28: =SUM(B14:B27) -> 1735 | C28: =SUM(C14:C27) -> 1735 | D28: =SUM(D14:D27) -> 106188 | E28: =SUM(E14:E27) -> 773 | F28: =SUM(F14:F27) -> 369 | G28: =SUM(G14:G27) -> 593 | H28: =SUM(H14:H27) -> 0 | I28: =IFERROR(E28/B28,0) -> 0.44553314
A71: STATUT | B71: DOSSIERS
A72: Chargés | B72: =J6 -> 369
A73: Sauvés | B73: =G6 -> 773
A74: Non chargés | B74: =M6 -> 593
A75: Annulés | B75: =P6 -> 0
A110: TAGS EN DOUBLE — À VÉRIFIER (VRAI DOUBLON · STATUT DIFFÉRENT · LÉGITIME)
A111: ="VRAI DOUBLON : "&COUNTIF(BASE!$R$6:$R$1740,"VRAI DOUBLON")&" • STATUT DIFFÉRENT : "&COUNTIF(BASE!$R$6:$R$1740,"STATUT DIFFÉRENT")&" • LÉGITIME : "&COUNTIF(BASE!$R$6:$R$1740,"LÉGITIME") -> VRAI DOUBLON : 9 • STATUT DIFFÉRENT : 1 • LÉGITIME : 16
A112: CIE | B112: DATE | D112: N° VOL | F112: N° TAG | H112: OCC. | I112: TYPE
A113: =IFERROR(INDEX(BASE!$B$6:$B$1740,MATCH(ROWS($A$113:$A113),BASE!$Q$6:$Q$1740,0)),"") -> AT | B113: =IFERROR(INDEX(BASE!$A$6:$A$1740,MATCH(ROWS($A$113:$A113),BASE!$Q$6:$Q$1740,0)),"") -> 01/09/2026 | D113: =IFERROR(INDEX(BASE!$C$6:$C$1740,MATCH(ROWS($A$113:$A113),BASE!$Q$6:$Q$1740,0)),"") -> AT639 | F113: =IFERROR(INDEX(BASE!$E$6:$E$1740,MATCH(ROWS($A$113:$A113),BASE!$Q$6:$Q$1740,0)),"") -> AT844408 | H113: =IFERROR(INDEX(BASE!$P$6:$P$1740,MATCH(ROWS($A$113:$A113),BASE!$Q$6:$Q$1740,0)),"") -> 2 | I113: =IFERROR(INDEX(BASE!$R$6:$R$1740,MATCH(ROWS($A$113:$A113),BASE!$Q$6:$Q$1740,0)),"") -> VRAI DOUBLON
A114: =IFERROR(INDEX(BASE!$B$6:$B$1740,MATCH(ROWS($A$113:$A114),BASE!$Q$6:$Q$1740,0)),"") -> AT | B114: =IFERROR(INDEX(BASE!$A$6:$A$1740,MATCH(ROWS($A$113:$A114),BASE!$Q$6:$Q$1740,0)),"") -> 01/09/2026 | D114: =IFERROR(INDEX(BASE!$C$6:$C$1740,MATCH(ROWS($A$113:$A114),BASE!$Q$6:$Q$1740,0)),"") -> AT639 | F114: =IFERROR(INDEX(BASE!$E$6:$E$1740,MATCH(ROWS($A$113:$A114),BASE!$Q$6:$Q$1740,0)),"") -> AT844125 | H114: =IFERROR(INDEX(BASE!$P$6:$P$1740,MATCH(ROWS($A$113:$A114),BASE!$Q$6:$Q$1740,0)),"") -> 2 | I114: =IFERROR(INDEX(BASE!$R$6:$R$1740,MATCH(ROWS($A$113:$A114),BASE!$Q$6:$Q$1740,0)),"") -> VRAI DOUBLON
A115: =IFERROR(INDEX(BASE!$B$6:$B$1740,MATCH(ROWS($A$113:$A115),BASE!$Q$6:$Q$1740,0)),"") -> AI | B115: =IFERROR(INDEX(BASE!$A$6:$A$1740,MATCH(ROWS($A$113:$A115),BASE!$Q$6:$Q$1740,0)),"") -> 02/09/2026 | D115: =IFERROR(INDEX(BASE!$C$6:$C$1740,MATCH(ROWS($A$113:$A115),BASE!$Q$6:$Q$1740,0)),"") -> AI148 | F115: =IFERROR(INDEX(BASE!$E$6:$E$1740,MATCH(ROWS($A$113:$A115),BASE!$Q$6:$Q$1740,0)),"") -> AC487587 | H115: =IFERROR(INDEX(BASE!$P$6:$P$1740,MATCH(ROWS($A$113:$A115),BASE!$Q$6:$Q$1740,0)),"") -> 2 | I115: =IFERROR(INDEX(BASE!$R$6:$R$1740,MATCH(ROWS($A$113:$A115),BASE!$Q$6:$Q$1740,0)),"") -> VRAI DOUBLON
A116: =IFERROR(INDEX(BASE!$B$6:$B$1740,MATCH(ROWS($A$113:$A116),BASE!$Q$6:$Q$1740,0)),"") -> AI | B116: =IFERROR(INDEX(BASE!$A$6:$A$1740,MATCH(ROWS($A$113:$A116),BASE!$Q$6:$Q$1740,0)),"") -> 03/09/2026 | D116: =IFERROR(INDEX(BASE!$C$6:$C$1740,MATCH(ROWS($A$113:$A116),BASE!$Q$6:$Q$1740,0)),"") -> AI148 | F116: =IFERROR(INDEX(BASE!$E$6:$E$1740,MATCH(ROWS($A$113:$A116),BASE!$Q$6:$Q$1740,0)),"") -> AC552692 | H116: =IFERROR(INDEX(BASE!$P$6:$P$1740,MATCH(ROWS($A$113:$A116),BASE!$Q$6:$Q$1740,0)),"") -> 2 | I116: =IFERROR(INDEX(BASE!$R$6:$R$1740,MATCH(ROWS($A$113:$A116),BASE!$Q$6:$Q$1740,0)),"") -> LÉGITIME
A117: =IFERROR(INDEX(BASE!$B$6:$B$1740,MATCH(ROWS($A$113:$A117),BASE!$Q$6:$Q$1740,0)),"") -> AI | B117: =IFERROR(INDEX(BASE!$A$6:$A$1740,MATCH(ROWS($A$113:$A117),BASE!$Q$6:$Q$1740,0)),"") -> 03/09/2026 | D117: =IFERROR(INDEX(BASE!$C$6:$C$1740,MATCH(ROWS($A$113:$A117),BASE!$Q$6:$Q$1740,0)),"") -> AI148 | F117: =IFERROR(INDEX(BASE!$E$6:$E$1740,MATCH(ROWS($A$113:$A117),BASE!$Q$6:$Q$1740,0)),"") -> AC552694 | H117: =IFERROR(INDEX(BASE!$P$6:$P$1740,MATCH(ROWS($A$113:$A117),BASE!$Q$6:$Q$1740,0)),"") -> 2 | I117: =IFERROR(INDEX(BASE!$R$6:$R$1740,MATCH(ROWS($A$113:$A117),BASE!$Q$6:$Q$1740,0)),"") -> LÉGITIME
A118: =IFERROR(INDEX(BASE!$B$6:$B$1740,MATCH(ROWS($A$113:$A118),BASE!$Q$6:$Q$1740,0)),"") -> AI | B118: =IFERROR(INDEX(BASE!$A$6:$A$1740,MATCH(ROWS($A$113:$A118),BASE!$Q$6:$Q$1740,0)),"") -> 03/09/2026 | D118: =IFERROR(INDEX(BASE!$C$6:$C$1740,MATCH(ROWS($A$113:$A118),BASE!$Q$6:$Q$1740,0)),"") -> AI148 | F118: =IFERROR(INDEX(BASE!$E$6:$E$1740,MATCH(ROWS($A$113:$A118),BASE!$Q$6:$Q$1740,0)),"") -> AC552722 | H118: =IFERROR(INDEX(BASE!$P$6:$P$1740,MATCH(ROWS($A$113:$A118),BASE!$Q$6:$Q$1740,0)),"") -> 2 | I118: =IFERROR(INDEX(BASE!$R$6:$R$1740,MATCH(ROWS($A$113:$A118),BASE!$Q$6:$Q$1740,0)),"") -> LÉGITIME
A119: =IFERROR(INDEX(BASE!$B$6:$B$1740,MATCH(ROWS($A$113:$A119),BASE!$Q$6:$Q$1740,0)),"") -> AI | B119: =IFERROR(INDEX(BASE!$A$6:$A$1740,MATCH(ROWS($A$113:$A119),BASE!$Q$6:$Q$1740,0)),"") -> 03/09/2026 | D119: =IFERROR(INDEX(BASE!$C$6:$C$1740,MATCH(ROWS($A$113:$A119),BASE!$Q$6:$Q$1740,0)),"") -> AI148 | F119: =IFERROR(INDEX(BASE!$E$6:$E$1740,MATCH(ROWS($A$113:$A119),BASE!$Q$6:$Q$1740,0)),"") -> AC552723 | H119: =IFERROR(INDEX(BASE!$P$6:$P$1740,MATCH(ROWS($A$113:$A119),BASE!$Q$6:$Q$1740,0)),"") -> 2 | I119: =IFERROR(INDEX(BASE!$R$6:$R$1740,MATCH(ROWS($A$113:$A119),BASE!$Q$6:$Q$1740,0)),"") -> LÉGITIME
A120: =IFERROR(INDEX(BASE!$B$6:$B$1740,MATCH(ROWS($A$113:$A120),BASE!$Q$6:$Q$1740,0)),"") -> AI | B120: =IFERROR(INDEX(BASE!$A$6:$A$1740,MATCH(ROWS($A$113:$A120),BASE!$Q$6:$Q$1740,0)),"") -> 03/09/2026 | D120: =IFERROR(INDEX(BASE!$C$6:$C$1740,MATCH(ROWS($A$113:$A120),BASE!$Q$6:$Q$1740,0)),"") -> AI148 | F120: =IFERROR(INDEX(BASE!$E$6:$E$1740,MATCH(ROWS($A$113:$A120),BASE!$Q$6:$Q$1740,0)),"") -> AC552724 | H120: =IFERROR(INDEX(BASE!$P$6:$P$1740,MATCH(ROWS($A$113:$A120),BASE!$Q$6:$Q$1740,0)),"") -> 2 | I120: =IFERROR(INDEX(BASE!$R$6:$R$1740,MATCH(ROWS($A$113:$A120),BASE!$Q$6:$Q$1740,0)),"") -> LÉGITIME
A121: =IFERROR(INDEX(BASE!$B$6:$B$1740,MATCH(ROWS($A$113:$A121),BASE!$Q$6:$Q$1740,0)),"") -> SK | B121: =IFERROR(INDEX(BASE!$A$6:$A$1740,MATCH(ROWS($A$113:$A121),BASE!$Q$6:$Q$1740,0)),"") -> 04/09/2026 | D121: =IFERROR(INDEX(BASE!$C$6:$C$1740,MATCH(ROWS($A$113:$A121),BASE!$Q$6:$Q$1740,0)),"") -> SK568 | F121: =IFERROR(INDEX(BASE!$E$6:$E$1740,MATCH(ROWS($A$113:$A121),BASE!$Q$6:$Q$1740,0)),"") -> AF286191 | H121: =IFERROR(INDEX(BASE!$P$6:$P$1740,MATCH(ROWS($A$113:$A121),BASE!$Q$6:$Q$1740,0)),"") -> 2 | I121: =IFERROR(INDEX(BASE!$R$6:$R$1740,MATCH(ROWS($A$113:$A121),BASE!$Q$6:$Q$1740,0)),"") -> VRAI DOUBLON
...

Sheet DOSSIERS
A1: ALYZIA | DOSSIERS
A3: COMPTE RENDU DE SUPERVISION • SEPTEMBRE 2026 • TOUTES COMPAGNIES
A4: FILTRES EXCEL ▼ • Sélectionnez DATE, CIE, N° VOL, N° TAG ou STATUT dans les en-têtes. Toutes les journées sont regroupées ici.
A5: DATE | B5: CIE | C5: N° VOL | D5: HEURE DÉPART | E5: N° TAG | F5: NOMBRE BAGAGES | G5: VOL APPORT | H5: HEURE ARRIVÉE | I5: LOCALISATION | J5: REMARQUES | K5: ANOMALIE | L5: COMMENTAIRE/ACTION | M5: STATUT | N5: FAULT STATION
A6: 01/09/2026 | B6: AI | C6: AI148 | D6: 12:45 | E6: AC384224 | F6: 1 | G6: AC870 | H6: 10:08 | I6: ONLY BSM | L6: AUCUNE INJ SUR CDG / CHECK DONE AVEC GEH IDEM BAGS NON LISTE SUR LEUR LOAD SHEET AC870/31AUG//AHL DELAI 26474 | M6: NON CHARGÉ | N6: 21 - Bag left at station origin / correctly labelled
A7: 01/09/2026 | B7: AI | C7: AI148 | D7: 12:45 | E7: AC384225 | F7: 1 | G7: AC870 | H7: 10:08 | I7: ONLY BSM | L7: AUCUNE INJ SUR CDG / CHECK DONE AVEC GEH IDEM BAGS NON LISTE SUR LEUR LOAD SHEET AC870/31AUG//AHL DELAI 26474 | M7: NON CHARGÉ | N7: 21 - Bag left at station origin / correctly labelled
A8: 01/09/2026 | B8: AI | C8: AI142 | D8: 20:45 | E8: AF027425 | F8: 1 | G8: AF0009 | H8: 12:29 | I8: TBM DEPOSE HF DEPUIS 14H01 | K8: PAS DE MVT 18H55 | L8: PRIS EN CHARGE PAR BAGRUNNER ET DEPOSE SUR LA JETEE DEPART A 19H01 | M8: SAUVÉ
A9: 01/09/2026 | B9: AI | C9: AI142 | D9: 20:45 | E9: LO394849 | F9: 1 | G9: LO335 | H9: 19:02 | I9: T2C EJECTION C04 19H56 | K9: HOT CNX | L9: APPEL SUP GALERIE T2 A 20H06 ET SIGNALE POUR LE RECUPERER | M9: SAUVÉ
A10: 01/09/2026 | B10: AI | C10: AI142 | D10: 20:45 | E10: LO394856 | F10: 1 | G10: LO335 | H10: 19:02 | I10: T2C EJECTION C04 19H49 | K10: HOT CNX | L10: APPEL SUP GALERIE T2 A 20H06 ET SIGNALE POUR LE RECUPERER | M10: SAUVÉ
A11: 01/09/2026 | B11: AI | C11: AI142 | D11: 20:45 | E11: AF065477 | F11: 1 | G11: AF1159 | H11: 18:57 | I11: T2C INJECTION 19H54 | K11: PAS DE MVT 20H06 | L11: APPEL SUP GALERIE T2 A 20H06/DEMANDE DE VERIFIER EN REBUT DU C/BAG TROUVE EN REBUT C05 | M11: SAUVÉ
A12: 01/09/2026 | B12: AI | C12: AI142 | D12: 20:45 | E12: AF065418 | F12: 1 | G12: AF1159 | H12: 18:57 | I12: T2C EJECTION C04 19H56 | K12: HOT CNX | L12: APPEL SUP GALERIE T2 A 20H06 ET SIGNALE POUR LE RECUPERER | M12: SAUVÉ
A13: 01/09/2026 | B13: AT | C13: AT639 | D13: 22:00 | E13: AT844406 | F13: 1 | G13: LOCAL | I13: AUCUNE TRACE 21H20 | K13: BSM CREATION 20H31 | L13: APPEL LEADER AT A 21H20 CAR AUCUNE TRACE DU BAG/INJECTE SUITE A NOTRE APPEL/APPEL SUP GAL T2 A 21H30 ET SIGNALE QUE BAGS SUR TAPIS B01 | M13: SAUVÉ
A14: 01/09/2026 | B14: AT | C14: AT639 | D14: 22:00 | E14: AT844408 | F14: 1 | G14: LOCAL | I14: AUCUNE TRACE 21H20 | K14: BSM CREATION 20H31 | L14: APPEL LEADER AT A 21H20 CAR AUCUNE TRACE DU BAG/INJECTE SUITE A NOTRE APPEL/APPEL SUP GAL T2 A 21H30 ET SIGNALE QUE BAGS SUR TAPIS B01 | M14: SAUVÉ
A15: 01/09/2026 | B15: AT | C15: AT639 | D15: 22:00 | E15: AT844125 | F15: 1 | G15: LOCAL | I15: T2B CHECK IN BANQUE 25 20H06 | J15: HBAG | K15: BSM CREATION 20H06 | L15: APPEL LEADER AT A 21H20 CAR AUCUNE TRACE DU BAG/DIT QU'IL S'AGIT D'UN BAG CABINE SUREMENT PRIS A BORD PAR PAX | M15: CHARGÉ
A16: 01/09/2026 | B16: AV | C16: AV55 | D16: 08:55 | E16: AF878238 | F16: 1 | G16: AF1043/31AUG | H16: 21:51 | I16: TME HF 22H33 | K16: PAS DE MVT | L16: VU AVEC PILOTE AF 06H57/ APPEL GTB 07H00 PR VERIF INFRA/ TJS A CE NIVEAU VA ETRE DEPOSE AU TBM | M16: SAUVÉ
A17: 01/09/2026 | B17: AV | C17: AV55 | D17: 08:55 | E17: AF878043 | F17: 1 | G17: AF1043/31AUG | H17: 21:51 | I17: PAS DE LOC | K17: PAS DE LOC | L17: BIKE / VU AVEC PILOTE AF 06H57/ APPEL GTB 07H00 PR VERIF INFRA/ NEG / NEG QSE/ NEG A18/ NEG TBM/ NEG SBA//J+1 AHL PEIAV31185 | M17: NON CHARGÉ | N17: 54 - Interline bags not made available by inbound carrier per local agreement
A18: 01/09/2026 | B18: DE | C18: DE4264 | D18: 11:10 | E18: MK609826 | F18: 1 | G18: UNK | I18: 2E VERS TBM | K18: PAS DE MVT | L18: COB ADP CTC PR PREVENIR/DMD INTERVENTION BAGRUNNER 09H56 | M18: SAUVÉ
A19: 01/09/2026 | B19: DE | C19: DE4264 | D19: 11:10 | E19: MK609825 | F19: 1 | G19: UNK | I19: 2E VERS TBM | K19: PAS DE MVT | L19: COB ADP CTC PR PREVENIR/DMD INTERVENTION BAGRUNNER 09H57 | M19: SAUVÉ
A20: 01/09/2026 | B20: DE | C20: DE4264 | D20: 11:10 | E20: MK609827 | F20: 1 | G20: MK14 | H20: 08:20 | I20: PAS DE LOC//1ER LOC 16H08 2F | K20: 2F RETARD TRAITEMENT | L20: NEG TOUS SYSTEMES//J+1 AHL SEADE14645 | M20: NON CHARGÉ | N20: 53 - Interline MCT not available ( MCT initialement OK)
A21: 01/09/2026 | B21: DE | C21: DE4214 | D21: 16:45 | E21: DE372126 | F21: 1 | G21: LOCAL | I21: T3 EJECTION | L21: APPEL GALLERIE T3 16H02 / RETOUR CONFIRMANT QUE PLUS DE LOCAUX RESTANTS SUR JETEE DEPART | M21: CHARGÉ
A22: 01/09/2026 | B22: EI | C22: EI527 | D22: 17:00 | E22: EI129754 | F22: 1 | G22: RUSH | I22: AUCUNE TRACE | K22: BSM ONLY | L22: APPEL DIRBY T1 A 16H41 MAIS INJOIGNABLE | M22: NON CHARGÉ | N22: 21 - Bag left at station origin / correctly labelled
A23: 01/09/2026 | B23: EI | C23: EI527 | D23: 17:00 | E23: EI129755 | F23: 1 | G23: RUSH | I23: AUCUNE TRACE | K23: BSM ONLY | L23: APPEL DIRBY T1 A 16H41 MAIS INJOIGNABLE | M23: NON CHARGÉ | N23: 21 - Bag left at station origin / correctly labelled
A24: 01/09/2026 | B24: EI | C24: EI527 | D24: 17:00 | E24: EI129756 | F24: 1 | G24: RUSH | I24: AUCUNE TRACE | K24: BSM ONLY | L24: APPEL DIRBY T1 A 16H41 MAIS INJOIGNABLE | M24: NON CHARGÉ | N24: 21 - Bag left at station origin / correctly labelled
A25: 01/09/2026 | B25: EI | C25: EI527 | D25: 17:00 | E25: EI129757 | F25: 1 | G25: RUSH | I25: AUCUNE TRACE | K25: BSM ONLY | L25: APPEL DIRBY T1 A 16H41 MAIS INJOIGNABLE | M25: NON CHARGÉ | N25: 21 - Bag left at station origin / correctly labelled
A26: 01/09/2026 | B26: FI | C26: FI543 | D26: 14:00 | E26: LY872771 | F26: 1 | G26: LY221 | H26: 11:29 | I26: 2D HORS FORMAT | L26: APPEL TMB EN SLB 12H45 POUR DEMANDE A FAIRE DESCENDRE LE TRANSIT / RECU EN 2D HORS FORMAT H-15MN TOO LATE FWD FI547/01SEP | M26: NON CHARGÉ | N26: 54 - Interline bags not made available by inbound carrier per local agreement
A27: 01/09/2026 | B27: FI | C27: FI543 | D27: 14:00 | E27: LY872382 | F27: 1 | G27: LY221 | H27: 11:29 | I27: T2B EJECTION | L27: ENVOI BAG RUNNER CHECK DONE AU 2B MAIS PAS DE BAG VUE 12H45+13H00//AHL KEFFI16680 | M27: NON CHARGÉ | N27: 21 - Bag left at station origin / correctly labelled
A28: 01/09/2026 | B28: FI | C28: FI543 | D28: 14:00 | E28: AF040653 | F28: 1 | G28: AF7363 | I28: T1 HORS DFORMAT | K28: REFUSE PAR COORDO | L28: BAG NON CHARGE PAS DE RAISON RECU MAIS REFUSE PAR COORDO / SIZING OU CONDITIONNEMENT//FWD FI547/01SEP | M28: NON CHARGÉ | N28: 63 - Airport security
A29: 01/09/2026 | B29: FI | C29: FI543 | D29: 14:00 | E29: AF040488 | F29: 1 | G29: AF7363 | H29: 11:22 | I29: TBM T1-T2 | K29: RECU TARDIF | L29: PERTE DE TRACE APRES 2E TRI 11H47 / CHARGE EN NAVETTE TBM 14H08 POUR DEPOSE SAT 1 TOO LATE //FWD FI547/01SEP | M29: NON CHARGÉ | N29: 54 - Interline bags not made available by inbound carrier per local agreement
A30: 01/09/2026 | B30: FI | C30: FI547 | D30: 17:15 | E30: AF045927 | F30: 1 | G30: AF1179 | H30: 14:52 | I30: T1 EJECTION SJ06 16H50 | K30: HOT CNX | L30: APPEL GALERIE T1 A 18H00 ET SIGNALE | M30: SAUVÉ
A31: 01/09/2026 | B31: FI | C31: FI547 | D31: 17:15 | E31: G3268359 | F31: 1 | G31: AF0459 | H31: 11:42 | I31: CARROUSEL ARRIVEE 32 A 12H18 | K31: 2E SLB T2E 18H50 | L31: APPEL SALON AF 2E A 17H45/DMD SI BAG P/UP PAR PAX/NEG/RAPPEL AF 2E 18H57/DMD D'INJECTER LE BAG/APPEL GAL T1 20H32 ET SIGNALE EN WJ41 /RAPPEL 21H231 | M31: SAUVÉ
A32: 01/09/2026 | B32: JU | C32: JU241 | D32: 10:00 | E32: AF894926 | F32: 1 | G32: AF4199 | I32: TBM NAVETTE 09H59 | K32: RETARD TRAITEMENT | L32: TROP TARD PR INTERVENIR //J+1 AHL BEGJU36836 FWD JU241/02SEP | M32: NON CHARGÉ | N32: 64 - Unserviceable equipment / belt / sortation system
A33: 01/09/2026 | B33: JU | C33: JU243 | D33: 20:35 | E33: AA180770 | F33: 1 | G33: AA0042 | H33: 06:46 | I33: RUSH /2A HORS FORMAT 18H48 | K33: DEPOSE AU MAUVAIS ENDROIT | L33: SEULE TRACE APPARUE AU 2A HORS FORMAT A 18H48/ENVOI BAGRUNNER POUR VERIFIER A 19H56/NEG AU HF ET CYNO 2A | M33: NON CHARGÉ | N33: 21 - Bag left at station origin / correctly labelled
A34: 01/09/2026 | B34: LA | C34: LA8133 | D34: 13:00 | E34: LA327427 | F34: 1 | G34: LOCAL | I34: ONLY BSM | L34: POSSIBLE CABIN BAG / ENVOI BAG RUNNER POST DEPART 13H05 POUR VERIF T2C//J+1 PAS DE DOSSIER | M34: CHARGÉ
A35: 01/09/2026 | B35: RJ | C35: RJ118 | D35: 15:50 | E35: SK144375 | F35: 1 | G35: SK837 | H35: 11:59 | I35: TBM MC80 | L35: CONFIRME PAR AGENT TBM + AGENT PISTE BAG CERTAINEMENT CHARGE SANS SCAN / //J+1 FWD RJ118/02SEP | M35: NON CHARGÉ | N35: 63 - Airport security
A36: 01/09/2026 | B36: SK | C36: SK574 | D36: 10:30 | E36: AF881381 | F36: 1 | G36: AF345 | H36: 07:42 | I36: PAS DE LOC | K36: PAS DE LOC | L36: APPEL TBM80 10H01 POUR DEPOSER SOUS BORD | M36: SAUVÉ
A37: 01/09/2026 | B37: SK | C37: SK574 | D37: 10:30 | E37: AF012090 | F37: 1 | G37: AF345 | I37: PAS DE LOC | K37: PAS DE LOC | L37: NEG TOUS SYSTEMES //J+1 AHL ARNSK28352 | M37: NON CHARGÉ | N37: 21 - Bag left at station origin / correctly labelled
A38: 01/09/2026 | B38: SK | C38: SK566 | D38: 11:15 | E38: AF880683 | F38: 1 | G38: AF4199 | I38: DECHARGE NAVETTE 10H47 | K38: PAS DE MVT | L38: APPEL TBM80 11H01 PR SAVOIR OU ONT ÉTÉ DEPOSE LES BAGS/ PAS DE REPONSE DE LA GALERIE/ COORDO CONFIRME NE RIEN AVOIR SS BORD//FWD SK560/SK1273/01SEP | M38: NON CHARGÉ | N38: 54 - Interline bags not made available by inbound carrier per local agreement
A39: 01/09/2026 | B39: SK | C39: SK566 | D39: 11:15 | E39: AF883560 | F39: 1 | G39: AF4199 | I39: DECHARGE NAVETTE 10H47 | K39: PAS DE MVT | L39: APPEL TBM80 11H01 PR SAVOIR OU ONT ÉTÉ DEPOSE LES BAGS/ PAS DE REPONSE DE LA GALERIE/ COORDO CONFIRME NE RIEN AVOIR SS BORD FWD SK560/01SEP | M39: NON CHARGÉ | N39: 54 - Interline bags not made available by inbound carrier per local agreement
A40: 01/09/2026 | B40: SK | C40: SK566 | D40: 11:15 | E40: AF883636 | F40: 1 | G40: AF4199 | I40: DECHARGE NAVETTE 10H47 | K40: PAS DE MVT | L40: APPEL TBM80 11H01 PR SAVOIR OU ONT ÉTÉ DEPOSE LES BAGS/ PAS DE REPONSE DE LA GALERIE/ COORDO CONFIRME NE RIEN AVOIR SS BORD FWD SK560/01SEP | M40: NON CHARGÉ | N40: 54 - Interline bags not made available by inbound carrier per local agreement
A41: 01/09/2026 | B41: SK | C41: SK566 | D41: 11:15 | E41: AM294092 | F41: 1 | G41: AM44 | H41: 09:03 | I41: DECHARGE NAVETTE 10H47 | K41: PAS DE MVT | L41: APPEL TBM80 11H01 PR SAVOIR OU ONT ÉTÉ DEPOSE LES BAGS/ PAS DE REPONSE DE LA GALERIE/ COORDO CONFIRME NE RIEN AVOIR SS BORD FWD SK560/01SEP | M41: NON CHARGÉ | N41: 54 - Interline bags not made available by inbound carrier per local agreement
...

Sheet JOUR PAR JOUR
A1: ALYZIA | JOUR PAR JOUR
A3: COMPTE RENDU DE SUPERVISION • SEPTEMBRE 2026 • TOUTES COMPAGNIES
A5: DATE AFFICHÉE ▶ | C5: 24/09/2026
A7: RÉCAPITULATIF JOURNALIER • Changer la date en C5 | I7: DOSSIERS DU JOUR • Filtrer la date dans DOSSIERS pour consulter les détails
A8: CIE | B8: BAG. ATTENDUS | C8: DOSSIERS | D8: SAUVÉS | E8: CHARGÉS | F8: NON CHARGÉS | G8: ANNULÉS
A9: SK | B9: =IFERROR(INDEX('SYNTHÈSE PAR DATE'!$I$6:$I$35,MATCH($C$5,'SYNTHÈSE PAR DATE'!$A$6:$A$35,0)),0) -> 0 | C9: =COUNTIFS(BASE!$A$6:$A$1740,$C$5,BASE!$B$6:$B$1740,A9) -> 0 | D9: =COUNTIFS(BASE!$A$6:$A$1740,$C$5,BASE!$B$6:$B$1740,A9,BASE!$M$6:$M$1740,"SAUVÉ") -> 0 | E9: =COUNTIFS(BASE!$A$6:$A$1740,$C$5,BASE!$B$6:$B$1740,A9,BASE!$M$6:$M$1740,"CHARGÉ") -> 0 | F9: =COUNTIFS(BASE!$A$6:$A$1740,$C$5,BASE!$B$6:$B$1740,A9,BASE!$M$6:$M$1740,"NON CHARGÉ") -> 0 | G9: =COUNTIFS(BASE!$A$6:$A$1740,$C$5,BASE!$B$6:$B$1740,A9,BASE!$M$6:$M$1740,"ANNULÉ") -> 0 | I9: Le récapitulatif se met à jour avec la date C5. Pour afficher et imprimer les dossiers détaillés du jour, utilisez le filtre DATE de la feuille DOSSIERS.
A10: AI | B10: =IFERROR(INDEX('SYNTHÈSE PAR DATE'!$J$6:$J$35,MATCH($C$5,'SYNTHÈSE PAR DATE'!$A$6:$A$35,0)),0) -> 202 | C10: =COUNTIFS(BASE!$A$6:$A$1740,$C$5,BASE!$B$6:$B$1740,A10) -> 5 | D10: =COUNTIFS(BASE!$A$6:$A$1740,$C$5,BASE!$B$6:$B$1740,A10,BASE!$M$6:$M$1740,"SAUVÉ") -> 4 | E10: =COUNTIFS(BASE!$A$6:$A$1740,$C$5,BASE!$B$6:$B$1740,A10,BASE!$M$6:$M$1740,"CHARGÉ") -> 0 | F10: =COUNTIFS(BASE!$A$6:$A$1740,$C$5,BASE!$B$6:$B$1740,A10,BASE!$M$6:$M$1740,"NON CHARGÉ") -> 1 | G10: =COUNTIFS(BASE!$A$6:$A$1740,$C$5,BASE!$B$6:$B$1740,A10,BASE!$M$6:$M$1740,"ANNULÉ") -> 0
A11: EI | B11: =IFERROR(INDEX('SYNTHÈSE PAR DATE'!$K$6:$K$35,MATCH($C$5,'SYNTHÈSE PAR DATE'!$A$6:$A$35,0)),0) -> 632 | C11: =COUNTIFS(BASE!$A$6:$A$1740,$C$5,BASE!$B$6:$B$1740,A11) -> 8 | D11: =COUNTIFS(BASE!$A$6:$A$1740,$C$5,BASE!$B$6:$B$1740,A11,BASE!$M$6:$M$1740,"SAUVÉ") -> 0 | E11: =COUNTIFS(BASE!$A$6:$A$1740,$C$5,BASE!$B$6:$B$1740,A11,BASE!$M$6:$M$1740,"CHARGÉ") -> 3 | F11: =COUNTIFS(BASE!$A$6:$A$1740,$C$5,BASE!$B$6:$B$1740,A11,BASE!$M$6:$M$1740,"NON CHARGÉ") -> 5 | G11: =COUNTIFS(BASE!$A$6:$A$1740,$C$5,BASE!$B$6:$B$1740,A11,BASE!$M$6:$M$1740,"ANNULÉ") -> 0
A12: LA | B12: =IFERROR(INDEX('SYNTHÈSE PAR DATE'!$L$6:$L$35,MATCH($C$5,'SYNTHÈSE PAR DATE'!$A$6:$A$35,0)),0) -> 244 | C12: =COUNTIFS(BASE!$A$6:$A$1740,$C$5,BASE!$B$6:$B$1740,A12) -> 7 | D12: =COUNTIFS(BASE!$A$6:$A$1740,$C$5,BASE!$B$6:$B$1740,A12,BASE!$M$6:$M$1740,"SAUVÉ") -> 0 | E12: =COUNTIFS(BASE!$A$6:$A$1740,$C$5,BASE!$B$6:$B$1740,A12,BASE!$M$6:$M$1740,"CHARGÉ") -> 4 | F12: =COUNTIFS(BASE!$A$6:$A$1740,$C$5,BASE!$B$6:$B$1740,A12,BASE!$M$6:$M$1740,"NON CHARGÉ") -> 3 | G12: =COUNTIFS(BASE!$A$6:$A$1740,$C$5,BASE!$B$6:$B$1740,A12,BASE!$M$6:$M$1740,"ANNULÉ") -> 0
A13: HF | B13: =IFERROR(INDEX('SYNTHÈSE PAR DATE'!$M$6:$M$35,MATCH($C$5,'SYNTHÈSE PAR DATE'!$A$6:$A$35,0)),0) -> 482 | C13: =COUNTIFS(BASE!$A$6:$A$1740,$C$5,BASE!$B$6:$B$1740,A13) -> 4 | D13: =COUNTIFS(BASE!$A$6:$A$1740,$C$5,BASE!$B$6:$B$1740,A13,BASE!$M$6:$M$1740,"SAUVÉ") -> 0 | E13: =COUNTIFS(BASE!$A$6:$A$1740,$C$5,BASE!$B$6:$B$1740,A13,BASE!$M$6:$M$1740,"CHARGÉ") -> 4 | F13: =COUNTIFS(BASE!$A$6:$A$1740,$C$5,BASE!$B$6:$B$1740,A13,BASE!$M$6:$M$1740,"NON CHARGÉ") -> 0 | G13: =COUNTIFS(BASE!$A$6:$A$1740,$C$5,BASE!$B$6:$B$1740,A13,BASE!$M$6:$M$1740,"ANNULÉ") -> 0
A14: SB | B14: =IFERROR(INDEX('SYNTHÈSE PAR DATE'!$N$6:$N$35,MATCH($C$5,'SYNTHÈSE PAR DATE'!$A$6:$A$35,0)),0) -> 0 | C14: =COUNTIFS(BASE!$A$6:$A$1740,$C$5,BASE!$B$6:$B$1740,A14) -> 0 | D14: =COUNTIFS(BASE!$A$6:$A$1740,$C$5,BASE!$B$6:$B$1740,A14,BASE!$M$6:$M$1740,"SAUVÉ") -> 0 | E14: =COUNTIFS(BASE!$A$6:$A$1740,$C$5,BASE!$B$6:$B$1740,A14,BASE!$M$6:$M$1740,"CHARGÉ") -> 0 | F14: =COUNTIFS(BASE!$A$6:$A$1740,$C$5,BASE!$B$6:$B$1740,A14,BASE!$M$6:$M$1740,"NON CHARGÉ") -> 0 | G14: =COUNTIFS(BASE!$A$6:$A$1740,$C$5,BASE!$B$6:$B$1740,A14,BASE!$M$6:$M$1740,"ANNULÉ") -> 0
A15: DE | B15: =IFERROR(INDEX('SYNTHÈSE PAR DATE'!$O$6:$O$35,MATCH($C$5,'SYNTHÈSE PAR DATE'!$A$6:$A$35,0)),0) -> 140 | C15: =COUNTIFS(BASE!$A$6:$A$1740,$C$5,BASE!$B$6:$B$1740,A15) -> 1 | D15: =COUNTIFS(BASE!$A$6:$A$1740,$C$5,BASE!$B$6:$B$1740,A15,BASE!$M$6:$M$1740,"SAUVÉ") -> 0 | E15: =COUNTIFS(BASE!$A$6:$A$1740,$C$5,BASE!$B$6:$B$1740,A15,BASE!$M$6:$M$1740,"CHARGÉ") -> 0 | F15: =COUNTIFS(BASE!$A$6:$A$1740,$C$5,BASE!$B$6:$B$1740,A15,BASE!$M$6:$M$1740,"NON CHARGÉ") -> 1 | G15: =COUNTIFS(BASE!$A$6:$A$1740,$C$5,BASE!$B$6:$B$1740,A15,BASE!$M$6:$M$1740,"ANNULÉ") -> 0
A16: MH | B16: =IFERROR(INDEX('SYNTHÈSE PAR DATE'!$P$6:$P$35,MATCH($C$5,'SYNTHÈSE PAR DATE'!$A$6:$A$35,0)),0) -> 222 | C16: =COUNTIFS(BASE!$A$6:$A$1740,$C$5,BASE!$B$6:$B$1740,A16) -> 1 | D16: =COUNTIFS(BASE!$A$6:$A$1740,$C$5,BASE!$B$6:$B$1740,A16,BASE!$M$6:$M$1740,"SAUVÉ") -> 0 | E16: =COUNTIFS(BASE!$A$6:$A$1740,$C$5,BASE!$B$6:$B$1740,A16,BASE!$M$6:$M$1740,"CHARGÉ") -> 0 | F16: =COUNTIFS(BASE!$A$6:$A$1740,$C$5,BASE!$B$6:$B$1740,A16,BASE!$M$6:$M$1740,"NON CHARGÉ") -> 1 | G16: =COUNTIFS(BASE!$A$6:$A$1740,$C$5,BASE!$B$6:$B$1740,A16,BASE!$M$6:$M$1740,"ANNULÉ") -> 0
A17: RJ | B17: =IFERROR(INDEX('SYNTHÈSE PAR DATE'!$Q$6:$Q$35,MATCH($C$5,'SYNTHÈSE PAR DATE'!$A$6:$A$35,0)),0) -> 132 | C17: =COUNTIFS(BASE!$A$6:$A$1740,$C$5,BASE!$B$6:$B$1740,A17) -> 0 | D17: =COUNTIFS(BASE!$A$6:$A$1740,$C$5,BASE!$B$6:$B$1740,A17,BASE!$M$6:$M$1740,"SAUVÉ") -> 0 | E17: =COUNTIFS(BASE!$A$6:$A$1740,$C$5,BASE!$B$6:$B$1740,A17,BASE!$M$6:$M$1740,"CHARGÉ") -> 0 | F17: =COUNTIFS(BASE!$A$6:$A$1740,$C$5,BASE!$B$6:$B$1740,A17,BASE!$M$6:$M$1740,"NON CHARGÉ") -> 0 | G17: =COUNTIFS(BASE!$A$6:$A$1740,$C$5,BASE!$B$6:$B$1740,A17,BASE!$M$6:$M$1740,"ANNULÉ") -> 0
A18: AV | B18: =IFERROR(INDEX('SYNTHÈSE PAR DATE'!$R$6:$R$35,MATCH($C$5,'SYNTHÈSE PAR DATE'!$A$6:$A$35,0)),0) -> 220 | C18: =COUNTIFS(BASE!$A$6:$A$1740,$C$5,BASE!$B$6:$B$1740,A18) -> 4 | D18: =COUNTIFS(BASE!$A$6:$A$1740,$C$5,BASE!$B$6:$B$1740,A18,BASE!$M$6:$M$1740,"SAUVÉ") -> 1 | E18: =COUNTIFS(BASE!$A$6:$A$1740,$C$5,BASE!$B$6:$B$1740,A18,BASE!$M$6:$M$1740,"CHARGÉ") -> 3 | F18: =COUNTIFS(BASE!$A$6:$A$1740,$C$5,BASE!$B$6:$B$1740,A18,BASE!$M$6:$M$1740,"NON CHARGÉ") -> 0 | G18: =COUNTIFS(BASE!$A$6:$A$1740,$C$5,BASE!$B$6:$B$1740,A18,BASE!$M$6:$M$1740,"ANNULÉ") -> 0
A19: FI | B19: =IFERROR(INDEX('SYNTHÈSE PAR DATE'!$S$6:$S$35,MATCH($C$5,'SYNTHÈSE PAR DATE'!$A$6:$A$35,0)),0) -> 345 | C19: =COUNTIFS(BASE!$A$6:$A$1740,$C$5,BASE!$B$6:$B$1740,A19) -> 4 | D19: =COUNTIFS(BASE!$A$6:$A$1740,$C$5,BASE!$B$6:$B$1740,A19,BASE!$M$6:$M$1740,"SAUVÉ") -> 4 | E19: =COUNTIFS(BASE!$A$6:$A$1740,$C$5,BASE!$B$6:$B$1740,A19,BASE!$M$6:$M$1740,"CHARGÉ") -> 0 | F19: =COUNTIFS(BASE!$A$6:$A$1740,$C$5,BASE!$B$6:$B$1740,A19,BASE!$M$6:$M$1740,"NON CHARGÉ") -> 0 | G19: =COUNTIFS(BASE!$A$6:$A$1740,$C$5,BASE!$B$6:$B$1740,A19,BASE!$M$6:$M$1740,"ANNULÉ") -> 0
A20: AT | B20: =IFERROR(INDEX('SYNTHÈSE PAR DATE'!$T$6:$T$35,MATCH($C$5,'SYNTHÈSE PAR DATE'!$A$6:$A$35,0)),0) -> 421 | C20: =COUNTIFS(BASE!$A$6:$A$1740,$C$5,BASE!$B$6:$B$1740,A20) -> 31 | D20: =COUNTIFS(BASE!$A$6:$A$1740,$C$5,BASE!$B$6:$B$1740,A20,BASE!$M$6:$M$1740,"SAUVÉ") -> 15 | E20: =COUNTIFS(BASE!$A$6:$A$1740,$C$5,BASE!$B$6:$B$1740,A20,BASE!$M$6:$M$1740,"CHARGÉ") -> 0 | F20: =COUNTIFS(BASE!$A$6:$A$1740,$C$5,BASE!$B$6:$B$1740,A20,BASE!$M$6:$M$1740,"NON CHARGÉ") -> 16 | G20: =COUNTIFS(BASE!$A$6:$A$1740,$C$5,BASE!$B$6:$B$1740,A20,BASE!$M$6:$M$1740,"ANNULÉ") -> 0
A21: JU | B21: =IFERROR(INDEX('SYNTHÈSE PAR DATE'!$U$6:$U$35,MATCH($C$5,'SYNTHÈSE PAR DATE'!$A$6:$A$35,0)),0) -> 151 | C21: =COUNTIFS(BASE!$A$6:$A$1740,$C$5,BASE!$B$6:$B$1740,A21) -> 4 | D21: =COUNTIFS(BASE!$A$6:$A$1740,$C$5,BASE!$B$6:$B$1740,A21,BASE!$M$6:$M$1740,"SAUVÉ") -> 3 | E21: =COUNTIFS(BASE!$A$6:$A$1740,$C$5,BASE!$B$6:$B$1740,A21,BASE!$M$6:$M$1740,"CHARGÉ") -> 1 | F21: =COUNTIFS(BASE!$A$6:$A$1740,$C$5,BASE!$B$6:$B$1740,A21,BASE!$M$6:$M$1740,"NON CHARGÉ") -> 0 | G21: =COUNTIFS(BASE!$A$6:$A$1740,$C$5,BASE!$B$6:$B$1740,A21,BASE!$M$6:$M$1740,"ANNULÉ") -> 0
A22: LO | B22: =IFERROR(INDEX('SYNTHÈSE PAR DATE'!$V$6:$V$35,MATCH($C$5,'SYNTHÈSE PAR DATE'!$A$6:$A$35,0)),0) -> 205 | C22: =COUNTIFS(BASE!$A$6:$A$1740,$C$5,BASE!$B$6:$B$1740,A22) -> 8 | D22: =COUNTIFS(BASE!$A$6:$A$1740,$C$5,BASE!$B$6:$B$1740,A22,BASE!$M$6:$M$1740,"SAUVÉ") -> 6 | E22: =COUNTIFS(BASE!$A$6:$A$1740,$C$5,BASE!$B$6:$B$1740,A22,BASE!$M$6:$M$1740,"CHARGÉ") -> 1 | F22: =COUNTIFS(BASE!$A$6:$A$1740,$C$5,BASE!$B$6:$B$1740,A22,BASE!$M$6:$M$1740,"NON CHARGÉ") -> 1 | G22: =COUNTIFS(BASE!$A$6:$A$1740,$C$5,BASE!$B$6:$B$1740,A22,BASE!$M$6:$M$1740,"ANNULÉ") -> 0
A23: TOTAL JOUR | B23: =SUM(B9:B22) -> 3396 | C23: =SUM(C9:C22) -> 77 | D23: =SUM(D9:D22) -> 33 | E23: =SUM(E9:E22) -> 16 | F23: =SUM(F9:F22) -> 28 | G23: =SUM(G9:G22) -> 0

Sheet SYNTHÈSE PAR DATE
A1: ALYZIA | SYNTHÈSE PAR DATE
A3: COMPTE RENDU DE SUPERVISION • SEPTEMBRE 2026 • TOUTES COMPAGNIES
A4: SUIVI JOURNALIER • Calculé à partir de la BASE | I4: BAGAGES ATTENDUS PAR COMPAGNIE • Données source conservées
A5: DATE | B5: DOSSIERS | C5: BAGAGES TRAITÉS | D5: BAGAGES ATTENDUS | E5: SAUVÉS | F5: CHARGÉS | G5: NON CHARGÉS | H5: ANNULÉS | I5: SK | J5: AI | K5: EI | L5: LA | M5: HF | N5: SB | O5: DE | P5: MH | Q5: RJ | R5: AV | S5: FI | T5: AT | U5: JU | V5: LO
A6: 01/09/2026 | B6: =COUNTIF(BASE!$A$6:$A$1740,A6) -> 54 | C6: =SUMIF(BASE!$A$6:$A$1740,A6,BASE!$F$6:$F$1740) -> 54 | D6: =SUM(I6:V6) -> 3036 | E6: =COUNTIFS(BASE!$A$6:$A$1740,A6,BASE!$M$6:$M$1740,"SAUVÉ") -> 21 | F6: =COUNTIFS(BASE!$A$6:$A$1740,A6,BASE!$M$6:$M$1740,"CHARGÉ") -> 6 | G6: =COUNTIFS(BASE!$A$6:$A$1740,A6,BASE!$M$6:$M$1740,"NON CHARGÉ") -> 27 | H6: =COUNTIFS(BASE!$A$6:$A$1740,A6,BASE!$M$6:$M$1740,"ANNULÉ") -> 0 | I6: 394 | J6: 332 | K6: 402 | L6: 186 | M6: 399 | N6: 0 | O6: 91 | P6: 207 | Q6: 136 | R6: 149 | S6: 308 | T6: 334 | U6: 98 | V6: 0
A7: 02/09/2026 | B7: =COUNTIF(BASE!$A$6:$A$1740,A7) -> 83 | C7: =SUMIF(BASE!$A$6:$A$1740,A7,BASE!$F$6:$F$1740) -> 83 | D7: =SUM(I7:V7) -> 3093 | E7: =COUNTIFS(BASE!$A$6:$A$1740,A7,BASE!$M$6:$M$1740,"SAUVÉ") -> 25 | F7: =COUNTIFS(BASE!$A$6:$A$1740,A7,BASE!$M$6:$M$1740,"CHARGÉ") -> 3 | G7: =COUNTIFS(BASE!$A$6:$A$1740,A7,BASE!$M$6:$M$1740,"NON CHARGÉ") -> 55 | H7: =COUNTIFS(BASE!$A$6:$A$1740,A7,BASE!$M$6:$M$1740,"ANNULÉ") -> 0 | I7: 258 | J7: 389 | K7: 371 | L7: 167 | M7: 417 | N7: 356 | O7: 124 | P7: 128 | Q7: 106 | R7: 107 | S7: 207 | T7: 364 | U7: 99 | V7: 0
A8: 03/09/2026 | B8: =COUNTIF(BASE!$A$6:$A$1740,A8) -> 80 | C8: =SUMIF(BASE!$A$6:$A$1740,A8,BASE!$F$6:$F$1740) -> 80 | D8: =SUM(I8:V8) -> 3156 | E8: =COUNTIFS(BASE!$A$6:$A$1740,A8,BASE!$M$6:$M$1740,"SAUVÉ") -> 28 | F8: =COUNTIFS(BASE!$A$6:$A$1740,A8,BASE!$M$6:$M$1740,"CHARGÉ") -> 13 | G8: =COUNTIFS(BASE!$A$6:$A$1740,A8,BASE!$M$6:$M$1740,"NON CHARGÉ") -> 39 | H8: =COUNTIFS(BASE!$A$6:$A$1740,A8,BASE!$M$6:$M$1740,"ANNULÉ") -> 0 | I8: 398 | J8: 305 | K8: 501 | L8: 149 | M8: 509 | N8: 0 | O8: 119 | P8: 197 | Q8: 96 | R8: 151 | S8: 225 | T8: 412 | U8: 94 | V8: 0
A9: 04/09/2026 | B9: =COUNTIF(BASE!$A$6:$A$1740,A9) -> 64 | C9: =SUMIF(BASE!$A$6:$A$1740,A9,BASE!$F$6:$F$1740) -> 64 | D9: =SUM(I9:V9) -> 3419 | E9: =COUNTIFS(BASE!$A$6:$A$1740,A9,BASE!$M$6:$M$1740,"SAUVÉ") -> 45 | F9: =COUNTIFS(BASE!$A$6:$A$1740,A9,BASE!$M$6:$M$1740,"CHARGÉ") -> 3 | G9: =COUNTIFS(BASE!$A$6:$A$1740,A9,BASE!$M$6:$M$1740,"NON CHARGÉ") -> 16 | H9: =COUNTIFS(BASE!$A$6:$A$1740,A9,BASE!$M$6:$M$1740,"ANNULÉ") -> 0 | I9: 573 | J9: 262 | K9: 521 | L9: 163 | M9: 422 | N9: 0 | O9: 181 | P9: 220 | Q9: 125 | R9: 150 | S9: 341 | T9: 355 | U9: 106 | V9: 0
A10: 05/09/2026 | B10: =COUNTIF(BASE!$A$6:$A$1740,A10) -> 71 | C10: =SUMIF(BASE!$A$6:$A$1740,A10,BASE!$F$6:$F$1740) -> 71 | D10: =SUM(I10:V10) -> 4096 | E10: =COUNTIFS(BASE!$A$6:$A$1740,A10,BASE!$M$6:$M$1740,"SAUVÉ") -> 18 | F10: =COUNTIFS(BASE!$A$6:$A$1740,A10,BASE!$M$6:$M$1740,"CHARGÉ") -> 17 | G10: =COUNTIFS(BASE!$A$6:$A$1740,A10,BASE!$M$6:$M$1740,"NON CHARGÉ") -> 36 | H10: =COUNTIFS(BASE!$A$6:$A$1740,A10,BASE!$M$6:$M$1740,"ANNULÉ") -> 0 | I10: 508 | J10: 304 | K10: 567 | L10: 255 | M10: 422 | N10: 360 | O10: 206 | P10: 241 | Q10: 125 | R10: 154 | S10: 431 | T10: 391 | U10: 132 | V10: 0
A11: 06/09/2026 | B11: =COUNTIF(BASE!$A$6:$A$1740,A11) -> 59 | C11: =SUMIF(BASE!$A$6:$A$1740,A11,BASE!$F$6:$F$1740) -> 59 | D11: =SUM(I11:V11) -> 4518 | E11: =COUNTIFS(BASE!$A$6:$A$1740,A11,BASE!$M$6:$M$1740,"SAUVÉ") -> 13 | F11: =COUNTIFS(BASE!$A$6:$A$1740,A11,BASE!$M$6:$M$1740,"CHARGÉ") -> 25 | G11: =COUNTIFS(BASE!$A$6:$A$1740,A11,BASE!$M$6:$M$1740,"NON CHARGÉ") -> 21 | H11: =COUNTIFS(BASE!$A$6:$A$1740,A11,BASE!$M$6:$M$1740,"ANNULÉ") -> 0 | I11: 765 | J11: 332 | K11: 743 | L11: 279 | M11: 753 | N11: 0 | O11: 225 | P11: 183 | Q11: 163 | R11: 199 | S11: 338 | T11: 417 | U11: 121 | V11: 0
A12: 07/09/2026 | B12: =COUNTIF(BASE!$A$6:$A$1740,A12) -> 89 | C12: =SUMIF(BASE!$A$6:$A$1740,A12,BASE!$F$6:$F$1740) -> 89 | D12: =SUM(I12:V12) -> 4510 | E12: =COUNTIFS(BASE!$A$6:$A$1740,A12,BASE!$M$6:$M$1740,"SAUVÉ") -> 46 | F12: =COUNTIFS(BASE!$A$6:$A$1740,A12,BASE!$M$6:$M$1740,"CHARGÉ") -> 21 | G12: =COUNTIFS(BASE!$A$6:$A$1740,A12,BASE!$M$6:$M$1740,"NON CHARGÉ") -> 22 | H12: =COUNTIFS(BASE!$A$6:$A$1740,A12,BASE!$M$6:$M$1740,"ANNULÉ") -> 0 | I12: 827 | J12: 324 | K12: 599 | L12: 296 | M12: 390 | N12: 396 | O12: 284 | P12: 235 | Q12: 115 | R12: 158 | S12: 248 | T12: 498 | U12: 140 | V12: 0
A13: 08/09/2026 | B13: =COUNTIF(BASE!$A$6:$A$1740,A13) -> 56 | C13: =SUMIF(BASE!$A$6:$A$1740,A13,BASE!$F$6:$F$1740) -> 56 | D13: =SUM(I13:V13) -> 3124 | E13: =COUNTIFS(BASE!$A$6:$A$1740,A13,BASE!$M$6:$M$1740,"SAUVÉ") -> 39 | F13: =COUNTIFS(BASE!$A$6:$A$1740,A13,BASE!$M$6:$M$1740,"CHARGÉ") -> 6 | G13: =COUNTIFS(BASE!$A$6:$A$1740,A13,BASE!$M$6:$M$1740,"NON CHARGÉ") -> 11 | H13: =COUNTIFS(BASE!$A$6:$A$1740,A13,BASE!$M$6:$M$1740,"ANNULÉ") -> 0 | I13: 522 | J13: 298 | K13: 489 | L13: 163 | M13: 375 | N13: 0 | O13: 145 | P13: 222 | Q13: 112 | R13: 97 | S13: 259 | T13: 324 | U13: 118 | V13: 0
A14: 09/09/2026 | B14: =COUNTIF(BASE!$A$6:$A$1740,A14) -> 107 | C14: =SUMIF(BASE!$A$6:$A$1740,A14,BASE!$F$6:$F$1740) -> 107 | D14: =SUM(I14:V14) -> 3564 | E14: =COUNTIFS(BASE!$A$6:$A$1740,A14,BASE!$M$6:$M$1740,"SAUVÉ") -> 59 | F14: =COUNTIFS(BASE!$A$6:$A$1740,A14,BASE!$M$6:$M$1740,"CHARGÉ") -> 20 | G14: =COUNTIFS(BASE!$A$6:$A$1740,A14,BASE!$M$6:$M$1740,"NON CHARGÉ") -> 28 | H14: =COUNTIFS(BASE!$A$6:$A$1740,A14,BASE!$M$6:$M$1740,"ANNULÉ") -> 0 | I14: 513 | J14: 304 | K14: 592 | L14: 212 | M14: 383 | N14: 317 | O14: 95 | P14: 157 | Q14: 145 | R14: 127 | S14: 284 | T14: 307 | U14: 128 | V14: 0
A15: 10/09/2026 | B15: =COUNTIF(BASE!$A$6:$A$1740,A15) -> 42 | C15: =SUMIF(BASE!$A$6:$A$1740,A15,BASE!$F$6:$F$1740) -> 42 | D15: =SUM(I15:V15) -> 3277 | E15: =COUNTIFS(BASE!$A$6:$A$1740,A15,BASE!$M$6:$M$1740,"SAUVÉ") -> 7 | F15: =COUNTIFS(BASE!$A$6:$A$1740,A15,BASE!$M$6:$M$1740,"CHARGÉ") -> 11 | G15: =COUNTIFS(BASE!$A$6:$A$1740,A15,BASE!$M$6:$M$1740,"NON CHARGÉ") -> 24 | H15: =COUNTIFS(BASE!$A$6:$A$1740,A15,BASE!$M$6:$M$1740,"ANNULÉ") -> 0 | I15: 0 | J15: 257 | K15: 551 | L15: 227 | M15: 521 | N15: 0 | O15: 154 | P15: 210 | Q15: 168 | R15: 155 | S15: 274 | T15: 413 | U15: 162 | V15: 185
A16: 11/09/2026 | B16: =COUNTIF(BASE!$A$6:$A$1740,A16) -> 32 | C16: =SUMIF(BASE!$A$6:$A$1740,A16,BASE!$F$6:$F$1740) -> 32 | D16: =SUM(I16:V16) -> 3104 | E16: =COUNTIFS(BASE!$A$6:$A$1740,A16,BASE!$M$6:$M$1740,"SAUVÉ") -> 7 | F16: =COUNTIFS(BASE!$A$6:$A$1740,A16,BASE!$M$6:$M$1740,"CHARGÉ") -> 9 | G16: =COUNTIFS(BASE!$A$6:$A$1740,A16,BASE!$M$6:$M$1740,"NON CHARGÉ") -> 16 | H16: =COUNTIFS(BASE!$A$6:$A$1740,A16,BASE!$M$6:$M$1740,"ANNULÉ") -> 0 | I16: 0 | J16: 301 | K16: 546 | L16: 260 | M16: 399 | N16: 0 | O16: 174 | P16: 238 | Q16: 108 | R16: 91 | S16: 346 | T16: 293 | U16: 147 | V16: 201
A17: 12/09/2026 | B17: =COUNTIF(BASE!$A$6:$A$1740,A17) -> 63 | C17: =SUMIF(BASE!$A$6:$A$1740,A17,BASE!$F$6:$F$1740) -> 63 | D17: =SUM(I17:V17) -> 4038 | E17: =COUNTIFS(BASE!$A$6:$A$1740,A17,BASE!$M$6:$M$1740,"SAUVÉ") -> 40 | F17: =COUNTIFS(BASE!$A$6:$A$1740,A17,BASE!$M$6:$M$1740,"CHARGÉ") -> 12 | G17: =COUNTIFS(BASE!$A$6:$A$1740,A17,BASE!$M$6:$M$1740,"NON CHARGÉ") -> 11 | H17: =COUNTIFS(BASE!$A$6:$A$1740,A17,BASE!$M$6:$M$1740,"ANNULÉ") -> 0 | I17: 0 | J17: 317 | K17: 576 | L17: 317 | M17: 476 | N17: 410 | O17: 266 | P17: 222 | Q17: 164 | R17: 161 | S17: 294 | T17: 402 | U17: 174 | V17: 259
... A35: 30/09/2026 | B35: =COUNTIF(BASE!$A$6:$A$1740,A35) -> 55 | C35: =SUMIF(BASE!$A$6:$A$1740,A35,BASE!$F$6:$F$1740) -> 55 | D35: =SUM(I35:V35) -> 3761 | E35: =COUNTIFS(BASE!$A$6:$A$1740,A35,BASE!$M$6:$M$1740,"SAUVÉ") -> 36 | F35: =COUNTIFS(BASE!$A$6:$A$1740,A35,BASE!$M$6:$M$1740,"CHARGÉ") -> 11 | G35: =COUNTIFS(BASE!$A$6:$A$1740,A35,BASE!$M$6:$M$1740,"NON CHARGÉ") -> 8 | H35: =COUNTIFS(BASE!$A$6:$A$1740,A35,BASE!$M$6:$M$1740,"ANNULÉ") -> 0 | I35: 0 | J35: 412 | K35: 535 | L35: 331 | M35: 379 | N35: 311 | O35: 205 | P35: 251 | Q35: 120 | R35: 224 | S35: 310 | T35: 301 | U35: 153 | V35: 229
A36: TOTAL SEPTEMBRE | B36: =SUM(B6:B35) -> 1735 | C36: =SUM(C6:C35) -> 1735 | D36: =SUM(D6:D35) -> 106188 | E36: =SUM(E6:E35) -> 773 | F36: =SUM(F6:F35) -> 369 | G36: =SUM(G6:G35) -> 593 | H36: =SUM(H6:H35) -> 0 | I36: =SUM(I6:I35) -> 4758 | ... V36: =SUM(V6:V35) -> 4866

Sheet BASE
A1: ALYZIA | BASE DE DONNÉES | AZ1: STATUT | BA1: DOSSIERS
AZ2: SAUVÉS | BA2: =RÉCAPITULATIF!G6 -> 773
A3: COMPTE RENDU DE SUPERVISION • SEPTEMBRE 2026 • TOUTES COMPAGNIES | AZ3: CHARGÉS | BA3: =RÉCAPITULATIF!J6 -> 369
A4: SOURCE DES DONNÉES • Valeurs du fichier transmis, heures normalisées et préfixes de vol affichés | AZ4: NON CHARGÉS | BA4: =RÉCAPITULATIF!M6 -> 593
A5: DATE | B5: CIE | C5: N° VOL | D5: HEURE DÉPART | E5: N° TAG | F5: NOMBRE BAGAGES | G5: VOL APPORT | H5: HEURE ARRIVÉE | I5: LOCALISATION | J5: REMARQUES | K5: ANOMALIE | L5: COMMENTAIRE/ACTION | M5: STATUT | N5: FAULT STATION | P5: OCCURRENCES TAG | Q5: RANG DOUBLON | R5: TYPE DOUBLON | AZ5: ANNULÉS | BA5: =RÉCAPITULATIF!P6 -> 0
A6: 01/09/2026 | B6: AI | C6: AI148 | D6: 12:45 | E6: AC384224 | F6: 1 | G6: AC870 | H6: 10:08 | I6: ONLY BSM | L6: AUCUNE INJ SUR CDG / CHECK DONE AVEC GEH IDEM BAGS NON LISTE SUR LEUR LOAD SHEET AC870/31AUG//AHL DELAI 26474 | M6: NON CHARGÉ | N6: 21 - Bag left at station origin / correctly labelled | P6: =COUNTIF($E$6:$E$1740,E6) -> 1 | Q6: =IF(AND(P6>1,COUNTIF($E$6:E6,E6)=1),MAX($Q$5:Q5)+1,"") | R6: =IF(Q6="","",IF(COUNTIFS($E$6:$E$1740,E6,$A$6:$A$1740,A6,$C$6:$C$1740,C6)<P6,"LÉGITIME",IF(COUNTIFS($E$6:$E$1740,E6,$A$6:$A$1740,A6,$C$6:$C$1740,C6,$M$6:$M$1740,M6)<P6,"STATUT DIFFÉRENT","VRAI DOUBLON")))
A7: 01/09/2026 | B7: AI | C7: AI148 | D7: 12:45 | E7: AC384225 | F7: 1 | G7: AC870 | H7: 10:08 | I7: ONLY BSM | L7: AUCUNE INJ SUR CDG / CHECK DONE AVEC GEH IDEM BAGS NON LISTE SUR LEUR LOAD SHEET AC870/31AUG//AHL DELAI 26474 | M7: NON CHARGÉ | N7: 21 - Bag left at station origin / correctly labelled | P7: =COUNTIF($E$6:$E$1740,E7) -> 1 | Q7: =IF(AND(P7>1,COUNTIF($E$6:E7,E7)=1),MAX($Q$5:Q6)+1,"") | R7: =IF(Q7="","",IF(COUNTIFS($E$6:$E$1740,E7,$A$6:$A$1740,A7,$C$6:$C$1740,C7)<P7,"LÉGITIME",IF(COUNTIFS($E$6:$E$1740,E7,$A$6:$A$1740,A7,$C$6:$C$1740,C7,$M$6:$M$1740,M7)<P7,"STATUT DIFFÉRENT","VRAI DOUBLON")))
A8: 01/09/2026 | B8: AI | C8: AI142 | D8: 20:45 | E8: AF027425 | F8: 1 | G8: AF0009 | H8: 12:29 | I8: TBM DEPOSE HF DEPUIS 14H01 | K8: PAS DE MVT 18H55 | L8: PRIS EN CHARGE PAR BAGRUNNER ET DEPOSE SUR LA JETEE DEPART A 19H01 | M8: SAUVÉ | P8: =COUNTIF($E$6:$E$1740,E8) -> 1 | Q8: =IF(AND(P8>1,COUNTIF($E$6:E8,E8)=1),MAX($Q$5:Q7)+1,"") | R8: =IF(Q8="","",IF(COUNTIFS($E$6:$E$1740,E8,$A$6:$A$1740,A8,$C$6:$C$1740,C8)<P8,"LÉGITIME",IF(COUNTIFS($E$6:$E$1740,E8,$A$6:$A$1740,A8,$C$6:$C$1740,C8,$M$6:$M$1740,M8)<P8,"STATUT DIFFÉRENT","VRAI DOUBLON")))
A9: 01/09/2026 | B9: AI | C9: AI142 | D9: 20:45 | E9: LO394849 | F9: 1 | G9: LO335 | H9: 19:02 | I9: T2C EJECTION C04 19H56 | K9: HOT CNX | L9: APPEL SUP GALERIE T2 A 20H06 ET SIGNALE POUR LE RECUPERER | M9: SAUVÉ | P9: =COUNTIF($E$6:$E$1740,E9) -> 1 | Q9: =IF(AND(P9>1,COUNTIF($E$6:E9,E9)=1),MAX($Q$5:Q8)+1,"") | R9: =IF(Q9="","",IF(COUNTIFS($E$6:$E$1740,E9,$A$6:$A$1740,A9,$C$6:$C$1740,C9)<P9,"LÉGITIME",IF(COUNTIFS($E$6:$E$1740,E9,$A$6:$A$1740,A9,$C$6:$C$1740,C9,$M$6:$M$1740,M9)<P9,"STATUT DIFFÉRENT","VRAI DOUBLON")))
A10: 01/09/2026 | B10: AI | C10: AI142 | D10: 20:45 | E10: LO394856 | F10: 1 | G10: LO335 | H10: 19:02 | I10: T2C EJECTION C04 19H49 | K10: HOT CNX | L10: APPEL SUP GALERIE T2 A 20H06 ET SIGNALE POUR LE RECUPERER | M10: SAUVÉ | P10: =COUNTIF($E$6:$E$1740,E10) -> 1 | Q10: =IF(AND(P10>1,COUNTIF($E$6:E10,E10)=1),MAX($Q$5:Q9)+1,"") | R10: =IF(Q10="","",IF(COUNTIFS($E$6:$E$1740,E10,$A$6:$A$1740,A10,$C$6:$C$1740,C10)<P10,"LÉGITIME",IF(COUNTIFS($E$6:$E$1740,E10,$A$6:$A$1740,A10,$C$6:$C$1740,C10,$M$6:$M$1740,M10)<P10,"STATUT DIFFÉRENT","VRAI DOUBLON")))
A11: 01/09/2026 | B11: AI | C11: AI142 | D11: 20:45 | E11: AF065477 | F11: 1 | G11: AF1159 | H11: 18:57 | I11: T2C INJECTION 19H54 | K11: PAS DE MVT 20H06 | L11: APPEL SUP GALERIE T2 A 20H06/DEMANDE DE VERIFIER EN REBUT DU C/BAG TROUVE EN REBUT C05 | M11: SAUVÉ | P11: =COUNTIF($E$6:$E$1740,E11) -> 1 | Q11: =IF(AND(P11>1,COUNTIF($E$6:E11,E11)=1),MAX($Q$5:Q10)+1,"") | R11: =IF(Q11="","",IF(COUNTIFS($E$6:$E$1740,E11,$A$6:$A$1740,A11,$C$6:$C$1740,C11)<P11,"LÉGITIME",IF(COUNTIFS($E$6:$E$1740,E11,$A$6:$A$1740,A11,$C$6:$C$1740,C11,$M$6:$M$1740,M11)<P11,"STATUT DIFFÉRENT","VRAI DOUBLON")))
A12: 01/09/2026 | B12: AI | C12: AI142 | D12: 20:45 | E12: AF065418 | F12: 1 | G12: AF1159 | H12: 18:57 | I12: T2C EJECTION C04 19H56 | K12: HOT CNX | L12: APPEL SUP GALERIE T2 A 20H06 ET SIGNALE POUR LE RECUPERER | M12: SAUVÉ | P12: =COUNTIF($E$6:$E$1740,E12) -> 1 | Q12: =IF(AND(P12>1,COUNTIF($E$6:E12,E12)=1),MAX($Q$5:Q11)+1,"") | R12: =IF(Q12="","",IF(COUNTIFS($E$6:$E$1740,E12,$A$6:$A$1740,A12,$C$6:$C$1740,C12)<P12,"LÉGITIME",IF(COUNTIFS($E$6:$E$1740,E12,$A$6:$A$1740,A12,$C$6:$C$1740,C12,$M$6:$M$1740,M12)<P12,"STATUT DIFFÉRENT","VRAI DOUBLON")))
A13: 01/09/2026 | B13: AT | C13: AT639 | D13: 22:00 | E13: AT844406 | F13: 1 | G13: LOCAL | I13: AUCUNE TRACE 21H20 | K13: BSM CREATION 20H31 | L13: APPEL LEADER AT A 21H20 CAR AUCUNE TRACE DU BAG/INJECTE SUITE A NOTRE APPEL/APPEL SUP GAL T2 A 21H30 ET SIGNALE QUE BAGS SUR TAPIS B01 | M13: SAUVÉ | P13: =COUNTIF($E$6:$E$1740,E13) -> 1 | Q13: =IF(AND(P13>1,COUNTIF($E$6:E13,E13)=1),MAX($Q$5:Q12)+1,"") | R13: =IF(Q13="","",IF(COUNTIFS($E$6:$E$1740,E13,$A$6:$A$1740,A13,$C$6:$C$1740,C13)<P13,"LÉGITIME",IF(COUNTIFS($E$6:$E$1740,E13,$A$6:$A$1740,A13,$C$6:$C$1740,C13,$M$6:$M$1740,M13)<P13,"STATUT DIFFÉRENT","VRAI DOUBLON")))
A14: 01/09/2026 | B14: AT | C14: AT639 | D14: 22:00 | E14: AT844408 | F14: 1 | G14: LOCAL | I14: AUCUNE TRACE 21H20 | K14: BSM CREATION 20H31 | L14: APPEL LEADER AT A 21H20 CAR AUCUNE TRACE DU BAG/INJECTE SUITE A NOTRE APPEL/APPEL SUP GAL T2 A 21H30 ET SIGNALE QUE BAGS SUR TAPIS B01 | M14: SAUVÉ | P14: =COUNTIF($E$6:$E$1740,E14) -> 2 | Q14: =IF(AND(P14>1,COUNTIF($E$6:E14,E14)=1),MAX($Q$5:Q13)+1,"") -> 1 | R14: =IF(Q14="","",IF(COUNTIFS($E$6:$E$1740,E14,$A$6:$A$1740,A14,$C$6:$C$1740,C14)<P14,"LÉGITIME",IF(COUNTIFS($E$6:$E$1740,E14,$A$6:$A$1740,A14,$C$6:$C$1740,C14,$M$6:$M$1740,M14)<P14,"STATUT DIFFÉRENT","VRAI DOUBLON"))) -> VRAI DOUBLON
A15: 01/09/2026 | B15: AT | C15: AT639 | D15: 22:00 | E15: AT844125 | F15: 1 | G15: LOCAL | I15: T2B CHECK IN BANQUE 25 20H06 | J15: HBAG | K15: BSM CREATION 20H06 | L15: APPEL LEADER AT A 21H20 CAR AUCUNE TRACE DU BAG/DIT QU'IL S'AGIT D'UN BAG CABINE SUREMENT PRIS A BORD PAR PAX | M15: CHARGÉ | P15: =COUNTIF($E$6:$E$1740,E15) -> 2 | Q15: =IF(AND(P15>1,COUNTIF($E$6:E15,E15)=1),MAX($Q$5:Q14)+1,"") -> 2 | R15: =IF(Q15="","",IF(COUNTIFS($E$6:$E$1740,E15,$A$6:$A$1740,A15,$C$6:$C$1740,C15)<P15,"LÉGITIME",IF(COUNTIFS($E$6:$E$1740,E15,$A$6:$A$1740,A15,$C$6:$C$1740,C15,$M$6:$M$1740,M15)<P15,"STATUT DIFFÉRENT","VRAI DOUBLON"))) -> VRAI DOUBLON
A16: 01/09/2026 | B16: AV | C16: AV55 | D16: 08:55 | E16: AF878238 | F16: 1 | G16: AF1043/31AUG | H16: 21:51 | I16: TME HF 22H33 | K16: PAS DE MVT | L16: VU AVEC PILOTE AF 06H57/ APPEL GTB 07H00 PR VERIF INFRA/ TJS A CE NIVEAU VA ETRE DEPOSE AU TBM | M16: SAUVÉ | P16: =COUNTIF($E$6:$E$1740,E16) -> 1 | Q16: =IF(AND(P16>1,COUNTIF($E$6:E16,E16)=1),MAX($Q$5:Q15)+1,"") | R16: =IF(Q16="","",IF(COUNTIFS($E$6:$E$1740,E16,$A$6:$A$1740,A16,$C$6:$C$1740,C16)<P16,"LÉGITIME",IF(COUNTIFS($E$6:$E$1740,E16,$A$6:$A$1740,A16,$C$6:$C$1740,C16,$M$6:$M$1740,M16)<P16,"STATUT DIFFÉRENT","VRAI DOUBLON")))
A17: 01/09/2026 | B17: AV | C17: AV55 | D17: 08:55 | E17: AF878043 | F17: 1 | G17: AF1043/31AUG | H17: 21:51 | I17: PAS DE LOC | K17: PAS DE LOC | L17: BIKE / VU AVEC PILOTE AF 06H57/ APPEL GTB 07H00 PR VERIF INFRA/ NEG / NEG QSE/ NEG A18/ NEG TBM/ NEG SBA//J+1 AHL PEIAV31185 | M17: NON CHARGÉ | N17: 54 - Interline bags not made available by inbound carrier per local agreement | P17: =COUNTIF($E$6:$E$1740,E17) -> 1 | Q17: =IF(AND(P17>1,COUNTIF($E$6:E17,E17)=1),MAX($Q$5:Q16)+1,"") | R17: =IF(Q17="","",IF(COUNTIFS($E$6:$E$1740,E17,$A$6:$A$1740,A17,$C$6:$C$1740,C17)<P17,"LÉGITIME",IF(COUNTIFS($E$6:$E$1740,E17,$A$6:$A$1740,A17,$C$6:$C$1740,C17,$M$6:$M$1740,M17)<P17,"STATUT DIFFÉRENT","VRAI DOUBLON")))
A18: 01/09/2026 | B18: DE | C18: DE4264 | D18: 11:10 | E18: MK609826 | F18: 1 | G18: UNK | I18: 2E VERS TBM | K18: PAS DE MVT | L18: COB ADP CTC PR PREVENIR/DMD INTERVENTION BAGRUNNER 09H56 | M18: SAUVÉ | P18: =COUNTIF($E$6:$E$1740,E18) -> 1 | Q18: =IF(AND(P18>1,COUNTIF($E$6:E18,E18)=1),MAX($Q$5:Q17)+1,"") | R18: =IF(Q18="","",IF(COUNTIFS($E$6:$E$1740,E18,$A$6:$A$1740,A18,$C$6:$C$1740,C18)<P18,"LÉGITIME",IF(COUNTIFS($E$6:$E$1740,E18,$A$6:$A$1740,A18,$C$6:$C$1740,C18,$M$6:$M$1740,M18)<P18,"STATUT DIFFÉRENT","VRAI DOUBLON")))
A19: 01/09/2026 | B19: DE | C19: DE4264 | D19: 11:10 | E19: MK609825 | F19: 1 | G19: UNK | I19: 2E VERS TBM | K19: PAS DE MVT | L19: COB ADP CTC PR PREVENIR/DMD INTERVENTION BAGRUNNER 09H57 | M19: SAUVÉ | P19: =COUNTIF($E$6:$E$1740,E19) -> 1 | Q19: =IF(AND(P19>1,COUNTIF($E$6:E19,E19)=1),MAX($Q$5:Q18)+1,"") | R19: =IF(Q19="","",IF(COUNTIFS($E$6:$E$1740,E19,$A$6:$A$1740,A19,$C$6:$C$1740,C19)<P19,"LÉGITIME",IF(COUNTIFS($E$6:$E$1740,E19,$A$6:$A$1740,A19,$C$6:$C$1740,C19,$M$6:$M$1740,M19)<P19,"STATUT DIFFÉRENT","VRAI DOUBLON")))
A20: 01/09/2026 | B20: DE | C20: DE4264 | D20: 11:10 | E20: MK609827 | F20: 1 | G20: MK14 | H20: 08:20 | I20: PAS DE LOC//1ER LOC 16H08 2F | K20: 2F RETARD TRAITEMENT | L20: NEG TOUS SYSTEMES//J+1 AHL SEADE14645 | M20: NON CHARGÉ | N20: 53 - Interline MCT not available ( MCT initialement OK) | P20: =COUNTIF($E$6:$E$1740,E20) -> 1 | Q20: =IF(AND(P20>1,COUNTIF($E$6:E20,E20)=1),MAX($Q$5:Q19)+1,"") | R20: =IF(Q20="","",IF(COUNTIFS($E$6:$E$1740,E20,$A$6:$A$1740,A20,$C$6:$C$1740,C20)<P20,"LÉGITIME",IF(COUNTIFS($E$6:$E$1740,E20,$A$6:$A$1740,A20,$C$6:$C$1740,C20,$M$6:$M$1740,M20)<P20,"STATUT DIFFÉRENT","VRAI DOUBLON")))
A21: 01/09/2026 | B21: DE | C21: DE4214 | D21: 16:45 | E21: DE372126 | F21: 1 | G21: LOCAL | I21: T3 EJECTION | L21: APPEL GALLERIE T3 16H02 / RETOUR CONFIRMANT QUE PLUS DE LOCAUX RESTANTS SUR JETEE DEPART | M21: CHARGÉ | P21: =COUNTIF($E$6:$E$1740,E21) -> 1 | Q21: =IF(AND(P21>1,COUNTIF($E$6:E21,E21)=1),MAX($Q$5:Q20)+1,"") | R21: =IF(Q21="","",IF(COUNTIFS($E$6:$E$1740,E21,$A$6:$A$1740,A21,$C$6:$C$1740,C21)<P21,"LÉGITIME",IF(COUNTIFS($E$6:$E$1740,E21,$A$6:$A$1740,A21,$C$6:$C$1740,C21,$M$6:$M$1740,M21)<P21,"STATUT DIFFÉRENT","VRAI DOUBLON")))
A22: 01/09/2026 | B22: EI | C22: EI527 | D22: 17:00 | E22: EI129754 | F22: 1 | G22: RUSH | I22: AUCUNE TRACE | K22: BSM ONLY | L22: APPEL DIRBY T1 A 16H41 MAIS INJOIGNABLE | M22: NON CHARGÉ | N22: 21 - Bag left at station origin / correctly labelled | P22: =COUNTIF($E$6:$E$1740,E22) -> 1 | Q22: =IF(AND(P22>1,COUNTIF($E$6:E22,E22)=1),MAX($Q$5:Q21)+1,"") | R22: =IF(Q22="","",IF(COUNTIFS($E$6:$E$1740,E22,$A$6:$A$1740,A22,$C$6:$C$1740,C22)<P22,"LÉGITIME",IF(COUNTIFS($E$6:$E$1740,E22,$A$6:$A$1740,A22,$C$6:$C$1740,C22,$M$6:$M$1740,M22)<P22,"STATUT DIFFÉRENT","VRAI DOUBLON")))
A23: 01/09/2026 | B23: EI | C23: EI527 | D23: 17:00 | E23: EI129755 | F23: 1 | G23: RUSH | I23: AUCUNE TRACE | K23: BSM ONLY | L23: APPEL DIRBY T1 A 16H41 MAIS INJOIGNABLE | M23: NON CHARGÉ | N23: 21 - Bag left at station origin / correctly labelled | P23: =COUNTIF($E$6:$E$1740,E23) -> 1 | Q23: =IF(AND(P23>1,COUNTIF($E$6:E23,E23)=1),MAX($Q$5:Q22)+1,"") | R23: =IF(Q23="","",IF(COUNTIFS($E$6:$E$1740,E23,$A$6:$A$1740,A23,$C$6:$C$1740,C23)<P23,"LÉGITIME",IF(COUNTIFS($E$6:$E$1740,E23,$A$6:$A$1740,A23,$C$6:$C$1740,C23,$M$6:$M$1740,M23)<P23,"STATUT DIFFÉRENT","VRAI DOUBLON")))
A24: 01/09/2026 | B24: EI | C24: EI527 | D24: 17:00 | E24: EI129756 | F24: 1 | G24: RUSH | I24: AUCUNE TRACE | K24: BSM ONLY | L24: APPEL DIRBY T1 A 16H41 MAIS INJOIGNABLE | M24: NON CHARGÉ | N24: 21 - Bag left at station origin / correctly labelled | P24: =COUNTIF($E$6:$E$1740,E24) -> 1 | Q24: =IF(AND(P24>1,COUNTIF($E$6:E24,E24)=1),MAX($Q$5:Q23)+1,"") | R24: =IF(Q24="","",IF(COUNTIFS($E$6:$E$1740,E24,$A$6:$A$1740,A24,$C$6:$C$1740,C24)<P24,"LÉGITIME",IF(COUNTIFS($E$6:$E$1740,E24,$A$6:$A$1740,A24,$C$6:$C$1740,C24,$M$6:$M$1740,M24)<P24,"STATUT DIFFÉRENT","VRAI DOUBLON")))
A25: 01/09/2026 | B25: EI | C25: EI527 | D25: 17:00 | E25: EI129757 | F25: 1 | G25: RUSH | I25: AUCUNE TRACE | K25: BSM ONLY | L25: APPEL DIRBY T1 A 16H41 MAIS INJOIGNABLE | M25: NON CHARGÉ | N25: 21 - Bag left at station origin / correctly labelled | P25: =COUNTIF($E$6:$E$1740,E25) -> 1 | Q25: =IF(AND(P25>1,COUNTIF($E$6:E25,E25)=1),MAX($Q$5:Q24)+1,"") | R25: =IF(Q25="","",IF(COUNTIFS($E$6:$E$1740,E25,$A$6:$A$1740,A25,$C$6:$C$1740,C25)<P25,"LÉGITIME",IF(COUNTIFS($E$6:$E$1740,E25,$A$6:$A$1740,A25,$C$6:$C$1740,C25,$M$6:$M$1740,M25)<P25,"STATUT DIFFÉRENT","VRAI DOUBLON")))
A26: 01/09/2026 | B26: FI | C26: FI543 | D26: 14:00 | E26: LY872771 | F26: 1 | G26: LY221 | H26: 11:29 | I26: 2D HORS FORMAT | L26: APPEL TMB EN SLB 12H45 POUR DEMANDE A FAIRE DESCENDRE LE TRANSIT / RECU EN 2D HORS FORMAT H-15MN TOO LATE FWD FI547/01SEP | M26: NON CHARGÉ | N26: 54 - Interline bags not made available by inbound carrier per local agreement | P26: =COUNTIF($E$6:$E$1740,E26) -> 1 | Q26: =IF(AND(P26>1,COUNTIF($E$6:E26,E26)=1),MAX($Q$5:Q25)+1,"") | R26: =IF(Q26="","",IF(COUNTIFS($E$6:$E$1740,E26,$A$6:$A$1740,A26,$C$6:$C$1740,C26)<P26,"LÉGITIME",IF(COUNTIFS($E$6:$E$1740,E26,$A$6:$A$1740,A26,$C$6:$C$1740,C26,$M$6:$M$1740,M26)<P26,"STATUT DIFFÉRENT","VRAI DOUBLON")))
A27: 01/09/2026 | B27: FI | C27: FI543 | D27: 14:00 | E27: LY872382 | F27: 1 | G27: LY221 | H27: 11:29 | I27: T2B EJECTION | L27: ENVOI BAG RUNNER CHECK DONE AU 2B MAIS PAS DE BAG VUE 12H45+13H00//AHL KEFFI16680 | M27: NON CHARGÉ | N27: 21 - Bag left at station origin / correctly labelled | P27: =COUNTIF($E$6:$E$1740,E27) -> 1 | Q27: =IF(AND(P27>1,COUNTIF($E$6:E27,E27)=1),MAX($Q$5:Q26)+1,"") | R27: =IF(Q27="","",IF(COUNTIFS($E$6:$E$1740,E27,$A$6:$A$1740,A27,$C$6:$C$1740,C27)<P27,"LÉGITIME",IF(COUNTIFS($E$6:$E$1740,E27,$A$6:$A$1740,A27,$C$6:$C$1740,C27,$M$6:$M$1740,M27)<P27,"STATUT DIFFÉRENT","VRAI DOUBLON")))
A28: 01/09/2026 | B28: FI | C28: FI543 | D28: 14:00 | E28: AF040653 | F28: 1 | G28: AF7363 | I28: T1 HORS DFORMAT | K28: REFUSE PAR COORDO | L28: BAG NON CHARGE PAS DE RAISON RECU MAIS REFUSE PAR COORDO / SIZING OU CONDITIONNEMENT//FWD FI547/01SEP | M28: NON CHARGÉ | N28: 63 - Airport security | P28: =COUNTIF($E$6:$E$1740,E28) -> 1 | Q28: =IF(AND(P28>1,COUNTIF($E$6:E28,E28)=1),MAX($Q$5:Q27)+1,"") | R28: =IF(Q28="","",IF(COUNTIFS($E$6:$E$1740,E28,$A$6:$A$1740,A28,$C$6:$C$1740,C28)<P28,"LÉGITIME",IF(COUNTIFS($E$6:$E$1740,E28,$A$6:$A$1740,A28,$C$6:$C$1740,C28,$M$6:$M$1740,M28)<P28,"STATUT DIFFÉRENT","VRAI DOUBLON")))
